Workbook

Sheet Guide
B1: Silva Annual Plan – Template Guide (v2)
B2: Built to the structure agreed in "Silva Plan – Revised Template Structure (v2)". Prepared by SPX for review.
B4: TABS
B5: Summary | C5: Category metrics, man-days and budget for the five categories, plus scenario budgets for comparison. Nothing is typed here.
B6: Settings | C6: Farm name, plan year, the +25% / +50% bands, working days, and staff settings.
B7: Nursery | C7: One tab per category (Nursery, Young Coffee, Matured Coffee, Infilling, Harvesting). See "How a category tab works" below.
B8: Monthly | C8: Monthly cost and man-days from the Chaka Buna plan rows of all five category tabs.
B9: Staff & Overheads | C9: Parked – not yet in the Summary or Monthly tabs.
B10: Benchmark Data | C10: Rates from all six B-Agro farm plans (2019 EFY). Source of every industry-average value.
B12: HOW A CATEGORY TAB WORKS
B13: 1. Plan basis (top of the tab): choose Industry average, +25%, +50% or Expert input. It sets the Chaka Buna plan row of every activity on the tab.
B14: 2. General information: enter the category metrics (areas, tree counts, beds…). Activity quantities link to these, and the Summary shows them.
B15: 3. Each activity has five rows: Industry average · +25% · +50% · Expert input · Chaka Buna plan. Only the Chaka Buna plan row counts in totals.
B16: 4. Cost per unit = man-days per unit × wage per man-day on every row. The bands raise the wage by 25% / 50%; man-days stay the same.
B17: 5. Enter the activity quantity per round once, on the Industry average row (green = already linked to a metric; yellow blank = type it).
B18: 6. The agronomist overwrites man-days, wage or frequency on the Expert input row (pre-filled with the industry average).
B19: 7. Activities with no industry-average rate always use the Expert input row, whatever the plan basis says.
B20: 8. Phasing % is entered on the Chaka Buna plan row (pre-filled from B-Agro's seasonal timing). It turns red if it does not add up to 100%.
B21: 9. Use the outline buttons (1 / 2) at the top-left of the sheet to collapse each activity to its Chaka Buna plan row.
B23: COLOUR CODE
B24: Blue text, yellow cell | C24: Input – type here.
B25: Green text, yellow cell | C25: Pre-filled suggestion (link to a benchmark or metric) – overwrite if needed.
B26: Green text | C26: Link from another tab – do not edit.
B27: Green row | C27: Chaka Buna plan row – the one that counts.
B28: Black text | C28: Calculation – do not edit.
B30: ABOUT THE BENCHMARKS
B31: • Industry average = Telli, Gawi and Chetu, the three B-Agro farms closest to Silva, counting only the farms that plan the activity.
B32: • Industry wage per man-day = average cost ÷ average man-days, so the Industry average row reproduces the three farms' average cost.
B33: • 124 activities: 102 have a rate at one or more of the three farms; 9 only at the other B-Agro farms (six-farm average pre-fills the Expert input row); 13 have no B-Agro rate (10 SPX additions and 3 B-Agro lines with no rate) – enter them on the Expert input row.
B34: • Benchmarks are B-Agro budgets, not actual costs.
C36: REVIEW LOG
B37: # | C37: Tab / code / cell | D37: Comment | E37: Raised by | F37: Date | G37: SPX response | H37: Status
B38: 1
B39: 2
B40: 3
B41: 4
B42: 5
B43: 6
B44: 7
B45: 8
...

Sheet Summary
B1: Silva Annual Plan – Summary
B2: ="Farm: "&Settings!$C$6&" | Plan year: "&Settings!$C$7 -> Farm: Chaka Buna Estate (Silva Forest Coffee) | Plan year: 2019 EFY (2026/27) – confirm
B3: Everything on this tab comes from the category tabs: metrics from each "General information" block, man-days and budget from the Chaka Buna plan rows.
B5: CATEGORY METRICS | G5: CHAKA BUNA PLAN | J5: BUDGET BY SCENARIO (for comparison)
B6: Category | C6: Metric (Amharic) | D6: Metric (English) | E6: Unit | F6: Quantity | G6: Plan basis | H6: Total man-days | I6: Budget (birr) | J6: Industry average | K6: +25% | L6: +50% | M6: Expert input
B7: Nursery | C7: =Nursery!D8 -> የሚተከል የቦታ ስፋት (ሄ/ር) | D7: =Nursery!C8 -> Plantation area | E7: =Nursery!E8 -> ha | F7: =Nursery!F8 -> 0 | G7: =Nursery!D4 -> Industry average | H7: =Nursery!N12 -> 0 | I7: =Nursery!O12 -> 0 | J7: =Nursery!O8 -> 0 | K7: =Nursery!O9 -> 0 | L7: =Nursery!O10 -> 0 | M7: =Nursery!O11 -> 0
C8: =Nursery!D9 -> የሚዘጋጅ ችግኝ ብዛት (ቁጥር) | D8: =Nursery!C9 -> Total seedlings | E8: =Nursery!E9 -> no. | F8: =Nursery!F9 -> 0
C9: =Nursery!D10 -> የችግኝ ጣቢያ ስፋት | D9: =Nursery!C10 -> Nursery site area | E9: =Nursery!E10 -> ha | F9: =Nursery!F10 -> 0
C10: =Nursery!D11 -> የዘር መደብ | D10: =Nursery!C11 -> Germination seedbeds | E10: =Nursery!E11 -> bed | F10: =Nursery!F11 -> 0
C11: =Nursery!D12 -> የፖሊቲዩብ መደብ | D11: =Nursery!C12 -> Polytube beds | E11: =Nursery!E12 -> bed | F11: =Nursery!F12 -> 0
B12: Young Coffee | C12: ='Young Coffee'!C7 -> የቡና እግር ብዛት (ቁጥር) | D12: ='Young Coffee'!B7 -> Total trees (net area) | E12: ='Young Coffee'!D7 -> no. | F12: ='Young Coffee'!E7 -> 0 | G12: ='Young Coffee'!C3 -> Industry average | H12: ='Young Coffee'!M11 -> 0 | I12: ='Young Coffee'!N11 -> 0 | J12: ='Young Coffee'!N7 -> 0 | K12: ='Young Coffee'!N8 -> 0 | L12: ='Young Coffee'!N9 -> 0 | M12: ='Young Coffee'!N10 -> 0
C13: ='Young Coffee'!C8 -> ጠቅላላ የማሳ ስፋት (ሄ/ር) | D13: ='Young Coffee'!B8 -> Gross area | E13: ='Young Coffee'!D8 -> ha | F13: ='Young Coffee'!E8 -> 0
C14: ='Young Coffee'!C9 -> የቡና እግር አማካይ (ሄ/ር) | D14: ='Young Coffee'!B9 -> Average trees per ha | E14: ='Young Coffee'!D9 -> trees/ha | F14: ='Young Coffee'!E9 -> 0
B15: Matured Coffee | C15: ='Matured Coffee'!C7 -> ጠቅላላ የመሬት (ሄ/ር) | D15: ='Matured Coffee'!B7 -> Total coffee area | E15: ='Matured Coffee'!D7 -> ha | F15: ='Matured Coffee'!E7 -> 0 | G15: ='Matured Coffee'!C3 -> Industry average | H15: ='Matured Coffee'!M11 -> 0 | I15: ='Matured Coffee'!N11 -> 0 | J15: ='Matured Coffee'!N7 -> 0 | K15: ='Matured Coffee'!N8 -> 0 | L15: ='Matured Coffee'!N9 -> 0 | M15: ='Matured Coffee'!N10 -> 0
C16: ='Matured Coffee'!C8 -> እናት ቡና እግር ብዛት (ቁጥር) | D16: ='Matured Coffee'!B8 -> Total mature trees (net area) | E16: ='Matured Coffee'!D8 -> no. | F16: ='Matured Coffee'!E8 -> 0
C17: ='Matured Coffee'!C9 -> የቡና እግር አማካይ (ሄ/ር) | D17: ='Matured Coffee'!B9 -> Average trees per ha | E17: ='Matured Coffee'!D9 -> trees/ha | F17: ='Matured Coffee'!E9 -> 0
C18: ='Matured Coffee'!C10 -> የሚጎነደል ቡና | D18: ='Matured Coffee'!B10 -> Trees to stump | E18: ='Matured Coffee'!D10 -> no. | F18: ='Matured Coffee'!E10 -> 0
B19: Infilling | C19: =Infilling!C7 -> ጠቅላላ የመሬት (ሄ/ር) | D19: =Infilling!B7 -> Total coffee area | E19: =Infilling!D7 -> ha | F19: =Infilling!E7 -> 0 | G19: =Infilling!C3 -> Industry average | H19: =Infilling!M11 -> 0 | I19: =Infilling!N11 -> 0 | J19: =Infilling!N7 -> 0 | K19: =Infilling!N8 -> 0 | L19: =Infilling!N9 -> 0 | M19: =Infilling!N10 -> 0
C20: =Infilling!C8 -> ሞተ ከዳ ቁጥር | D20: =Infilling!B8 -> Trees to infill | E20: =Infilling!D8 -> no. | F20: =Infilling!E8 -> 0
C21: =Infilling!C9 -> የቡና እግር አማካይ (ሄ/ር) | D21: =Infilling!B9 -> Average trees per ha (trees to infill ÷ area) | E21: =Infilling!D9 -> trees/ha | F21: =Infilling!E9 -> 0
B22: Harvesting & Related | C22: =Harvesting!C7 -> ምርታማ የቡና እግር ቁጥር | D22: =Harvesting!B7 -> Productive trees | E22: =Harvesting!D7 -> no. | F22: =Harvesting!E7 -> 0 | G22: =Harvesting!C3 -> Industry average | H22: =Harvesting!M11 -> 0 | I22: =Harvesting!N11 -> 0 | J22: =Harvesting!N7 -> 0 | K22: =Harvesting!N8 -> 0 | L22: =Harvesting!N9 -> 0 | M22: =Harvesting!N10 -> 0
C23: =Harvesting!C8 -> ጠቅላላ የቦታ ስፋት (ሄ/ር) | D23: =Harvesting!B8 -> Gross plantation area | E23: =Harvesting!D8 -> ha | F23: =Harvesting!E8 -> 0
C24: =Harvesting!C9 -> ምርታማነት አማካይ (ኩ/ል/ሄ/ር) | D24: =Harvesting!B9 -> Average productivity | E24: =Harvesting!D9 -> qt clean coffee/ha | F24: =Harvesting!E9 -> 0
C25: =Harvesting!C10 -> አጠቃላይ የሚመረት ንፁህ ቡና (ኩ/ል) | D25: =Harvesting!B10 -> Total clean coffee production | E25: =Harvesting!D10 -> qt | F25: =Harvesting!E10 -> 0
C26: =Harvesting!C11 -> ቀይ ቡና | D26: =Harvesting!B11 -> Red cherry to pick | E26: =Harvesting!D11 -> kg | F26: =Harvesting!E11 -> 0
C27: =Harvesting!C12 -> የቡና ማስጫ አልጋ | D27: =Harvesting!B12 -> Drying beds | E27: =Harvesting!D12 -> bed | F27: =Harvesting!E12 -> 0
C28: =Harvesting!C13 -> ደረቅ ቡና ኬሻ | D28: =Harvesting!B13 -> Dry cherry bags | E28: =Harvesting!D13 -> bag | F28: =Harvesting!E13 -> 0
B29: TOTAL – ALL FIELD WORK | H29: =H7+H12+H15+H19+H22 -> 0 | I29: =I7+I12+I15+I19+I22 -> 0 | J29: =J7+J12+J15+J19+J22 -> 0 | K29: =K7+K12+K15+K19+K22 -> 0 | L29: =L7+L12+L15+L19+L22 -> 0 | M29: =M7+M12+M15+M19+M22 -> 0
B30: =IF(ABS(I29-Monthly!B11)>0.5,"Check: Summary total differs from Monthly total","")

Sheet Settings
B2: Settings
B3: Values used across the workbook. Quantities now sit in each category tab ("General information" block).
B5: Setting | C5: Value | D5: Unit | E5: Source / note
B6: Farm | C6: Chaka Buna Estate (Silva Forest Coffee) | D6: text | E6: Appears in the tab headers.
B7: Plan year | C7: 2019 EFY (2026/27) – confirm | D7: text | E7: Months run Tikimt–Meskerem (Oct–Sep), as in the B-Agro plans. Confirm against Chaka Buna's financial year.
B8: Band 1 above industry average | C8: 0.25 | D8: % | E8: Applied to wage per man-day on the "+25%" rows. The row labels stay "+25%" if you change this value.
B9: Band 2 above industry average | C9: 0.5 | D9: % | E9: Applied to wage per man-day on the "+50%" rows. The row labels stay "+50%" if you change this value.
B10: Working days per month | C10: 26 | D10: days | E10: Converts monthly man-days into workers needed (Monthly tab).
B11: Employer pension contribution | C11: 0.11 | D11: % of salary | E11: Staff & Overheads tab only. Rate used in all B-Agro salary sheets.
B12: Salary increment for plan year | C12: 0.1 | D12: % of salary | E12: Staff & Overheads tab only. B-Agro applied 10% in its 2018 EFY Chetu plan. Assumption – confirm.
B13: Bonus | C13: 1 | D13: months of salary | E13: Staff & Overheads tab only. B-Agro plans budget one month. Assumption – confirm.

Sheet Nursery
B1: Nursery – activity plan and budget
B2: ="Farm: "&Settings!$C$6&" | Plan year: "&Settings!$C$7 -> Farm: Chaka Buna Estate (Silva Forest Coffee) | Plan year: 2019 EFY (2026/27) – confirm
C4: Plan basis (drop-down) ► | D4: Industry average | E4: Sets the Chaka Buna plan row of every activity on this tab. Activities with no industry-average rate always use the Expert input row.
C6: GENERAL INFORMATION | G6: CATEGORY TOTALS
C7: Metric (English) | D7: Metric (Amharic) | E7: Unit | F7: Quantity | G7: Rate scenario | N7: Total man-days | O7: Total cost (birr) | P7: Plan phasing (% of cost) | AB7: Plan monthly totals
C8: Plantation area | D8: የሚተከል የቦታ ስፋት (ሄ/ር) | E8: ha | G8: Industry average | N8: =SUMIF($G$18:$G$182,"Industry average",N$18:N$182) -> 0 | O8: =SUMIF($G$18:$G$182,"Industry average",O$18:O$182) -> 0
C9: Total seedlings | D9: የሚዘጋጅ ችግኝ ብዛት (ቁጥር) | E9: no. | G9: +25% | N9: =SUMIF($G$18:$G$182,"+25%",N$18:N$182) -> 0 | O9: =SUMIF($G$18:$G$182,"+25%",O$18:O$182) -> 0
C10: Nursery site area | D10: የችግኝ ጣቢያ ስፋት | E10: ha | G10: +50% | N10: =SUMIF($G$18:$G$182,"+50%",N$18:N$182) -> 0 | O10: =SUMIF($G$18:$G$182,"+50%",O$18:O$182) -> 0
C11: Germination seedbeds | D11: የዘር መደብ | E11: bed | G11: Expert input | N11: =SUMIF($G$18:$G$182,"Expert input",N$18:N$182) -> 0 | O11: =SUMIF($G$18:$G$182,"Expert input",O$18:O$182) -> 0
C12: Polytube beds | D12: የፖሊቲዩብ መደብ | E12: bed | G12: Chaka Buna plan – counts in Summary | N12: =SUMIF($G$18:$G$182,"Chaka Buna plan",N$18:N$182) -> 0 | O12: =SUMIF($G$18:$G$182,"Chaka Buna plan",O$18:O$182) -> 0 | P12: =IFERROR(AC12/$O$12,0) -> 0 | Q12: =IFERROR(AE12/$O$12,0) -> 0 | R12: =IFERROR(AG12/$O$12,0) -> 0 | S12: =IFERROR(AI12/$O$12,0) -> 0 | T12: =IFERROR(AK12/$O$12,0) -> 0 | U12: =IFERROR(AM12/$O$12,0) -> 0 | V12: =IFERROR(AO12/$O$12,0) -> 0 | W12: =IFERROR(AQ12/$O$12,0) -> 0 | X12: =IFERROR(AS12/$O$12,0) -> 0 | Y12: =IFERROR(AU12/$O$12,0) -> 0 | Z12: =IFERROR(AW12/$O$12,0) -> 0 | AA12: =IFERROR(AY12/$O$12,0) -> 0 | AB12: =SUM(AB18:AB182) -> 0 | AC12: =SUM(AC18:AC182) -> 0 | AD12: =SUM(AD18:AD182) -> 0 | AE12: =SUM(AE18:AE182) -> 0 | AF12: =SUM(AF18:AF182) -> 0 | AG12: =SUM(AG18:AG182) -> 0 | AH12: =SUM(AH18:AH182) -> 0 | AI12: =SUM(AI18:AI182) -> 0 | ... AY12: =SUM(AY18:AY182) -> 0
B16: ACTIVITY | G16: RATE (cost per unit = man-days × wage) | K16: QUANTITY | M16: TOTALS (calculated) | P16: PHASING – % of annual (input on the Chaka Buna plan row) | AB16: MONTHLY MAN-DAYS AND COST (Chaka Buna plan row)
B17: Code | C17: Activity | D17: Activity (Amharic) | E17: Sub-group | F17: Unit | G17: Rate scenario | H17: Man-days per unit | I17: Wage per man-day (birr) | J17: Cost per unit (birr) | K17: Activity quantity per round | L17: Frequency (times / year) | M17: Total activity quantity | N17: Total man-days per activity | O17: Total cost per activity (birr) | P17: Tikimt (Oct) | Q17: Hidar (Nov) | R17: Tahsas (Dec) | S17: Tir (Jan) | T17: Yekatit (Feb) | U17: Megabit (Mar) | V17: Miyazya (Apr) | W17: Ginbot (May) | X17: Sene (Jun) | Y17: Hamle (Jul) | Z17: Nehase (Aug) | AA17: Meskerem (Sep) | AB17: Tikimt (Oct) – man-days | AC17: Tikimt (Oct) – cost | AD17: Hidar (Nov) – man-days | AE17: Hidar (Nov) – cost | AF17: Tahsas (Dec) – man-days | AG17: Tahsas (Dec) – cost | AH17: Tir (Jan) – man-days | AI17: Tir (Jan) – cost | AJ17: Yekatit (Feb) – man-days | AK17: Yekatit (Feb) – cost | AL17: Megabit (Mar) – man-days | AM17: Megabit (Mar) – cost | AN17: Miyazya (Apr) – man-days | AO17: Miyazya (Apr) – cost | AP17: Ginbot (May) – man-days | AQ17: Ginbot (May) – cost | AR17: Sene (Jun) – man-days | AS17: Sene (Jun) – cost | AT17: Hamle (Jul) – man-days | AU17: Hamle (Jul) – cost | AV17: Nehase (Aug) – man-days | AW17: Nehase (Aug) – cost | AX17: Meskerem (Sep) – man-days | AY17: Meskerem (Sep) – cost
B18: NU-01 | C18: Land clearing | D18: ምንጣሮ | E18: Site preparation | F18: ha | G18: Industry average | H18: =IFERROR(INDEX('Benchmark Data'!$AC$7:$AC$130,MATCH($B18,'Benchmark Data'!$A$7:$A$130,0)),0) -> 20 | I18: =IFERROR(INDEX('Benchmark Data'!$AD$7:$AD$130,MATCH($B18,'Benchmark Data'!$A$7:$A$130,0)),0) -> 183.33333 | J18: =H18*I18 -> 3666.6667 | K18: =$F$10 -> 0 | L18: =IFERROR(INDEX('Benchmark Data'!$AE$7:$AE$130,MATCH($B18,'Benchmark Data'!$A$7:$A$130,0)),0) -> 1 | M18: =K18*L18 -> 0 | N18: =M18*H18 -> 0 | O18: =M18*J18 -> 0
B19: NU-01 | C19: Land clearing | D19: ምንጣሮ | E19: Site preparation | F19: ha | G19: +25% | H19: =H18 -> 20 | I19: =I18*(1+Settings!$C$8) -> 229.16667 | J19: =H19*I19 -> 4583.3333 | K19: =K18 -> 0 | L19: =L18 -> 1 | M19: =K19*L19 -> 0 | N19: =M19*H19 -> 0 | O19: =M19*J19 -> 0
B20: NU-01 | C20: Land clearing | D20: ምንጣሮ | E20: Site preparation | F20: ha | G20: +50% | H20: =H18 -> 20 | I20: =I18*(1+Settings!$C$9) -> 275 | J20: =H20*I20 -> 5500 | K20: =K18 -> 0 | L20: =L18 -> 1 | M20: =K20*L20 -> 0 | N20: =M20*H20 -> 0 | O20: =M20*J20 -> 0
B21: NU-01 | C21: Land clearing | D21: ምንጣሮ | E21: Site preparation | F21: ha | G21: Expert input | H21: =H18 -> 20 | I21: =I18 -> 183.33333 | J21: =H21*I21 -> 3666.6667 | K21: =K18 -> 0 | L21: =L18 -> 1 | M21: =K21*L21 -> 0 | N21: =M21*H21 -> 0 | O21: =M21*J21 -> 0
B22: NU-01 | C22: Land clearing | D22: ምንጣሮ | E22: Site preparation | F22: ha | G22: Chaka Buna plan | H22: =CHOOSE(IF(OR($D$4="Expert input",$J$18=0),4,IF($D$4="+25%",2,IF($D$4="+50%",3,1))),H18,H19,H20,H21) -> 20 | I22: =CHOOSE(IF(OR($D$4="Expert input",$J$18=0),4,IF($D$4="+25%",2,IF($D$4="+50%",3,1))),I18,I19,I20,I21) -> 183.33333 | J22: =H22*I22 -> 3666.6667 | K22: =K18 -> 0 | L22: =CHOOSE(IF(OR($D$4="Expert input",$J$18=0),4,IF($D$4="+25%",2,IF($D$4="+50%",3,1))),L18,L19,L20,L21) -> 1 | M22: =K22*L22 -> 0 | N22: =M22*H22 -> 0 | O22: =M22*J22 -> 0 | Q22: 1 | AB22: =P22*$N22 -> 0 | AC22: =P22*$O22 -> 0 | AD22: =Q22*$N22 -> 0 | AE22: =Q22*$O22 -> 0 | AF22: =R22*$N22 -> 0 | AG22: =R22*$O22 -> 0 | AH22: =S22*$N22 -> 0 | AI22: =S22*$O22 -> 0 | AJ22: =T22*$N22 -> 0 | AK22: =T22*$O22 -> 0 | AL22: =U22*$N22 -> 0 | AM22: =U22*$O22 -> 0 | AN22: =V22*$N22 -> 0 | AO22: =V22*$O22 -> 0 | AP22: =W22*$N22 -> 0 | AQ22: =W22*$O22 -> 0 | AR22: =X22*$N22 -> 0 | AS22: =X22*$O22 -> 0 | AT22: =Y22*$N22 -> 0 | AU22: =Y22*$O22 -> 0 | AV22: =Z22*$N22 -> 0 | AW22: =Z22*$O22 -> 0 | AX22: =AA22*$N22 -> 0 | AY22: =AA22*$O22 -> 0
B23: NU-02 | C23: Tree felling / stump removal | D23: ዛፍ መጣል / ጉቶ መንቀል | E23: Site preparation | F23: ha | G23: Industry average | H23: =IFERROR(INDEX('Benchmark Data'!$AC$7:$AC$130,MATCH($B23,'Benchmark Data'!$A$7:$A$130,0)),0) -> 24 | I23: =IFERROR(INDEX('Benchmark Data'!$AD$7:$AD$130,MATCH($B23,'Benchmark Data'!$A$7:$A$130,0)),0) -> 125 | J23: =H23*I23 -> 3000 | K23: =$F$10 -> 0 | L23: =IFERROR(INDEX('Benchmark Data'!$AE$7:$AE$130,MATCH($B23,'Benchmark Data'!$A$7:$A$130,0)),0) -> 1 | M23: =K23*L23 -> 0 | N23: =M23*H23 -> 0 | O23: =M23*J23 -> 0
B24: NU-02 | C24: Tree felling / stump removal | D24: ዛፍ መጣል / ጉቶ መንቀል | E24: Site preparation | F24: ha | G24: +25% | H24: =H23 -> 24 | I24: =I23*(1+Settings!$C$8) -> 156.25 | J24: =H24*I24 -> 3750 | K24: =K23 -> 0 | L24: =L23 -> 1 | M24: =K24*L24 -> 0 | N24: =M24*H24 -> 0 | O24: =M24*J24 -> 0
B25: NU-02 | C25: Tree felling / stump removal | D25: ዛፍ መጣል / ጉቶ መንቀል | E25: Site preparation | F25: ha | G25: +50% | H25: =H23 -> 24 | I25: =I23*(1+Settings!$C$9) -> 187.5 | J25: =H25*I25 -> 4500 | K25: =K23 -> 0 | L25: =L23 -> 1 | M25: =K25*L25 -> 0 | N25: =M25*H25 -> 0 | O25: =M25*J25 -> 0
B26: NU-02 | C26: Tree felling / stump removal | D26: ዛፍ መጣል / ጉቶ መንቀል | E26: Site preparation | F26: ha | G26: Expert input | H26: =H23 -> 24 | I26: =I23 -> 125 | J26: =H26*I26 -> 3000 | K26: =K23 -> 0 | L26: =L23 -> 1 | M26: =K26*L26 -> 0 | N26: =M26*H26 -> 0 | O26: =M26*J26 -> 0
B27: NU-02 | C27: Tree felling / stump removal | D27: ዛፍ መጣል / ጉቶ መንቀል | E27: Site preparation | F27: ha | G27: Chaka Buna plan | H27: =CHOOSE(IF(OR($D$4="Expert input",$J$23=0),4,IF($D$4="+25%",2,IF($D$4="+50%",3,1))),H23,H24,H25,H26) -> 24 | I27: =CHOOSE(IF(OR($D$4="Expert input",$J$23=0),4,IF($D$4="+25%",2,IF($D$4="+50%",3,1))),I23,I24,I25,I26) -> 125 | J27: =H27*I27 -> 3000 | K27: =K23 -> 0 | L27: =CHOOSE(IF(OR($D$4="Expert input",$J$23=0),4,IF($D$4="+25%",2,IF($D$4="+50%",3,1))),L23,L24,L25,L26) -> 1 | M27: =K27*L27 -> 0 | N27: =M27*H27 -> 0 | O27: =M27*J27 -> 0 | Q27: 1 | AB27: =P27*$N27 -> 0 | AC27: =P27*$O27 -> 0 | AD27: =Q27*$N27 -> 0 | AE27: =Q27*$O27 -> 0 | AF27: =R27*$N27 -> 0 | AG27: =R27*$O27 -> 0 | AH27: =S27*$N27 -> 0 | AI27: =S27*$O27 -> 0 | AJ27: =T27*$N27 -> 0 | AK27: =T27*$O27 -> 0 | AL27: =U27*$N27 -> 0 | AM27: =U27*$O27 -> 0 | AN27: =V27*$N27 -> 0 | AO27: =V27*$O27 -> 0 | AP27: =W27*$N27 -> 0 | AQ27: =W27*$O27 -> 0 | AR27: =X27*$N27 -> 0 | AS27: =X27*$O27 -> 0 | AT27: =Y27*$N27 -> 0 | AU27: =Y27*$O27 -> 0 | AV27: =Z27*$N27 -> 0 | AW27: =Z27*$O27 -> 0 | AX27: =AA27*$N27 -> 0 | AY27: =AA27*$O27 -> 0
B28: NU-03 | C28: Digging | D28: መቆፈር | E28: Site preparation | F28: ha | G28: Industry average | H28: =IFERROR(INDEX('Benchmark Data'!$AC$7:$AC$130,MATCH($B28,'Benchmark Data'!$A$7:$A$130,0)),0) -> 33.111111 | I28: =IFERROR(INDEX('Benchmark Data'!$AD$7:$AD$130,MATCH($B28,'Benchmark Data'!$A$7:$A$130,0)),0) -> 158.05369 | J28: =H28*I28 -> 5233.3333 | K28: =$F$10 -> 0 | L28: =IFERROR(INDEX('Benchmark Data'!$AE$7:$AE$130,MATCH($B28,'Benchmark Data'!$A$7:$A$130,0)),0) -> 1 | M28: =K28*L28 -> 0 | N28: =M28*H28 -> 0 | O28: =M28*J28 -> 0
B29: NU-03 | C29: Digging | D29: መቆፈር | E29: Site preparation | F29: ha | G29: +25% | H29: =H28 -> 33.111111 | I29: =I28*(1+Settings!$C$8) -> 197.56711 | J29: =H29*I29 -> 6541.6667 | K29: =K28 -> 0 | L29: =L28 -> 1 | M29: =K29*L29 -> 0 | N29: =M29*H29 -> 0 | O29: =M29*J29 -> 0
B30: NU-03 | C30: Digging | D30: መቆፈር | E30: Site preparation | F30: ha | G30: +50% | H30: =H28 -> 33.111111 | I30: =I28*(1+Settings!$C$9) -> 237.08054 | J30: =H30*I30 -> 7850 | K30: =K28 -> 0 | L30: =L28 -> 1 | M30: =K30*L30 -> 0 | N30: =M30*H30 -> 0 | O30: =M30*J30 -> 0
B31: NU-03 | C31: Digging | D31: መቆፈር | E31: Site preparation | F31: ha | G31: Expert input | H31: =H28 -> 33.111111 | I31: =I28 -> 158.05369 | J31: =H31*I31 -> 5233.3333 | K31: =K28 -> 0 | L31: =L28 -> 1 | M31: =K31*L31 -> 0 | N31: =M31*H31 -> 0 | O31: =M31*J31 -> 0
B32: NU-03 | C32: Digging | D32: መቆፈር | E32: Site preparation | F32: ha | G32: Chaka Buna plan | H32: =CHOOSE(IF(OR($D$4="Expert input",$J$28=0),4,IF($D$4="+25%",2,IF($D$4="+50%",3,1))),H28,H29,H30,H31) -> 33.111111 | I32: =CHOOSE(IF(OR($D$4="Expert input",$J$28=0),4,IF($D$4="+25%",2,IF($D$4="+50%",3,1))),I28,I29,I30,I31) -> 158.05369 | J32: =H32*I32 -> 5233.3333 | K32: =K28 -> 0 | L32: =CHOOSE(IF(OR($D$4="Expert input",$J$28=0),4,IF($D$4="+25%",2,IF($D$4="+50%",3,1))),L28,L29,L30,L31) -> 1 | M32: =K32*L32 -> 0 | N32: =M32*H32 -> 0 | O32: =M32*J32 -> 0 | Q32: 1 | AB32: =P32*$N32 -> 0 | AC32: =P32*$O32 -> 0 | AD32: =Q32*$N32 -> 0 | AE32: =Q32*$O32 -> 0 | AF32: =R32*$N32 -> 0 | AG32: =R32*$O32 -> 0 | AH32: =S32*$N32 -> 0 | AI32: =S32*$O32 -> 0 | AJ32: =T32*$N32 -> 0 | AK32: =T32*$O32 -> 0 | AL32: =U32*$N32 -> 0 | AM32: =U32*$O32 -> 0 | AN32: =V32*$N32 -> 0 | AO32: =V32*$O32 -> 0 | AP32: =W32*$N32 -> 0 | AQ32: =W32*$O32 -> 0 | AR32: =X32*$N32 -> 0 | AS32: =X32*$O32 -> 0 | AT32: =Y32*$N32 -> 0 | AU32: =Y32*$O32 -> 0 | AV32: =Z32*$N32 -> 0 | AW32: =Z32*$O32 -> 0 | AX32: =AA32*$N32 -> 0 | AY32: =AA32*$O32 -> 0
B33: NU-04 | C33: Trash removal | D33: ጥራጎ ማስወገድ | E33: Site preparation | F33: ha | G33: Industry average | H33: =IFERROR(INDEX('Benchmark Data'!$AC$7:$AC$130,MATCH($B33,'Benchmark Data'!$A$7:$A$130,0)),0) -> 15 | I33: =IFERROR(INDEX('Benchmark Data'!$AD$7:$AD$130,MATCH($B33,'Benchmark Data'!$A$7:$A$130,0)),0) -> 160 | J33: =H33*I33 -> 2400 | K33: =$F$10 -> 0 | L33: =IFERROR(INDEX('Benchmark Data'!$AE$7:$AE$130,MATCH($B33,'Benchmark Data'!$A$7:$A$130,0)),0) -> 1 | M33: =K33*L33 -> 0 | N33: =M33*H33 -> 0 | O33: =M33*J33 -> 0
B34: NU-04 | C34: Trash removal | D34: ጥራጎ ማስወገድ | E34: Site preparation | F34: ha | G34: +25% | H34: =H33 -> 15 | I34: =I33*(1+Settings!$C$8) -> 200 | J34: =H34*I34 -> 3000 | K34: =K33 -> 0 | L34: =L33 -> 1 | M34: =K34*L34 -> 0 | N34: =M34*H34 -> 0 | O34: =M34*J34 -> 0
B35: NU-04 | C35: Trash removal | D35: ጥራጎ ማስወገድ | E35: Site preparation | F35: ha | G35: +50% | H35: =H33 -> 15 | I35: =I33*(1+Settings!$C$9) -> 240 | J35: =H35*I35 -> 3600 | K35: =K33 -> 0 | L35: =L33 -> 1 | M35: =K35*L35 -> 0 | N35: =M35*H35 -> 0 | O35: =M35*J35 -> 0
B36: NU-04 | C36: Trash removal | D36: ጥራጎ ማስወገድ | E36: Site preparation | F36: ha | G36: Expert input | H36: =H33 -> 15 | I36: =I33 -> 160 | J36: =H36*I36 -> 2400 | K36: =K33 -> 0 | L36: =L33 -> 1 | M36: =K36*L36 -> 0 | N36: =M36*H36 -> 0 | O36: =M36*J36 -> 0
B37: NU-04 | C37: Trash removal | D37: ጥራጎ ማስወገድ | E37: Site preparation | F37: ha | G37: Chaka Buna plan | H37: =CHOOSE(IF(OR($D$4="Expert input",$J$33=0),4,IF($D$4="+25%",2,IF($D$4="+50%",3,1))),H33,H34,H35,H36) -> 15 | I37: =CHOOSE(IF(OR($D$4="Expert input",$J$33=0),4,IF($D$4="+25%",2,IF($D$4="+50%",3,1))),I33,I34,I35,I36) -> 160 | J37: =H37*I37 -> 2400 | K37: =K33 -> 0 | L37: =CHOOSE(IF(OR($D$4="Expert input",$J$33=0),4,IF($D$4="+25%",2,IF($D$4="+50%",3,1))),L33,L34,L35,L36) -> 1 | M37: =K37*L37 -> 0 | N37: =M37*H37 -> 0 | O37: =M37*J37 -> 0 | Q37: 1 | AB37: =P37*$N37 -> 0 | AC37: =P37*$O37 -> 0 | AD37: =Q37*$N37 -> 0 | AE37: =Q37*$O37 -> 0 | AF37: =R37*$N37 -> 0 | AG37: =R37*$O37 -> 0 | AH37: =S37*$N37 -> 0 | AI37: =S37*$O37 -> 0 | AJ37: =T37*$N37 -> 0 | AK37: =T37*$O37 -> 0 | AL37: =U37*$N37 -> 0 | AM37: =U37*$O37 -> 0 | AN37: =V37*$N37 -> 0 | AO37: =V37*$O37 -> 0 | AP37: =W37*$N37 -> 0 | AQ37: =W37*$O37 -> 0 | AR37: =X37*$N37 -> 0 | AS37: =X37*$O37 -> 0 | AT37: =Y37*$N37 -> 0 | AU37: =Y37*$O37 -> 0 | AV37: =Z37*$N37 -> 0 | AW37: =Z37*$O37 -> 0 | AX37: =AA37*$N37 -> 0 | AY37: =AA37*$O37 -> 0
B38: NU-05 | C38: Topsoil heaping | D38: ለም አፈር መቆለል | E38: Soil & polytube | F38: m³ | G38: Industry average | H38: =IFERROR(INDEX('Benchmark Data'!$AC$7:$AC$130,MATCH($B38,'Benchmark Data'!$A$7:$A$130,0)),0) -> 0.56666667 | I38: =IFERROR(INDEX('Benchmark Data'!$AD$7:$AD$130,MATCH($B38,'Benchmark Data'!$A$7:$A$130,0)),0) -> 100 | J38: =H38*I38 -> 56.666667 | L38: =IFERROR(INDEX('Benchmark Data'!$AE$7:$AE$130,MATCH($B38,'Benchmark Data'!$A$7:$A$130,0)),0) -> 1 | M38: =K38*L38 -> 0 | N38: =M38*H38 -> 0 | O38: =M38*J38 -> 0
B39: NU-05 | C39: Topsoil heaping | D39: ለም አፈር መቆለል | E39: Soil & polytube | F39: m³ | G39: +25% | H39: =H38 -> 0.56666667 | I39: =I38*(1+Settings!$C$8) -> 125 | J39: =H39*I39 -> 70.833333 | K39: =K38 -> 0 | L39: =L38 -> 1 | M39: =K39*L39 -> 0 | N39: =M39*H39 -> 0 | O39: =M39*J39 -> 0
B40: NU-05 | C40: Topsoil heaping | D40: ለም አፈር መቆለል | E40: Soil & polytube | F40: m³ | G40: +50% | H40: =H38 -> 0.56666667 | I40: =I38*(1+Settings!$C$9) -> 150 | J40: =H40*I40 -> 85 | K40: =K38 -> 0 | L40: =L38 -> 1 | M40: =K40*L40 -> 0 | N40: =M40*H40 -> 0 | O40: =M40*J40 -> 0
B41: NU-05 | C41: Topsoil heaping | D41: ለም አፈር መቆለል | E41: Soil & polytube | F41: m³ | G41: Expert input | H41: =H38 -> 0.56666667 | I41: =I38 -> 100 | J41: =H41*I41 -> 56.666667 | K41: =K38 -> 0 | L41: =L38 -> 1 | M41: =K41*L41 -> 0 | N41: =M41*H41 -> 0 | O41: =M41*J41 -> 0
B42: NU-05 | C42: Topsoil heaping | D42: ለም አፈር መቆለል | E42: Soil & polytube | F42: m³ | G42: Chaka Buna plan | H42: =CHOOSE(IF(OR($D$4="Expert input",$J$38=0),4,IF($D$4="+25%",2,IF($D$4="+50%",3,1))),H38,H39,H40,H41) -> 0.56666667 | I42: =CHOOSE(IF(OR($D$4="Expert input",$J$38=0),4,IF($D$4="+25%",2,IF($D$4="+50%",3,1))),I38,I39,I40,I41) -> 100 | J42: =H42*I42 -> 56.666667 | K42: =K38 -> 0 | L42: =CHOOSE(IF(OR($D$4="Expert input",$J$38=0),4,IF($D$4="+25%",2,IF($D$4="+50%",3,1))),L38,L39,L40,L41) -> 1 | M42: =K42*L42 -> 0 | N42: =M42*H42 -> 0 | O42: =M42*J42 -> 0 | Q42: 0.67 | R42: 0.33 | AB42: =P42*$N42 -> 0 | AC42: =P42*$O42 -> 0 | AD42: =Q42*$N42 -> 0 | AE42: =Q42*$O42 -> 0 | AF42: =R42*$N42 -> 0 | AG42: =R42*$O42 -> 0 | AH42: =S42*$N42 -> 0 | AI42: =S42*$O42 -> 0 | AJ42: =T42*$N42 -> 0 | AK42: =T42*$O42 -> 0 | AL42: =U42*$N42 -> 0 | AM42: =U42*$O42 -> 0 | AN42: =V42*$N42 -> 0 | AO42: =V42*$O42 -> 0 | AP42: =W42*$N42 -> 0 | AQ42: =W42*$O42 -> 0 | AR42: =X42*$N42 -> 0 | AS42: =X42*$O42 -> 0 | AT42: =Y42*$N42 -> 0 | AU42: =Y42*$O42 -> 0 | AV42: =Z42*$N42 -> 0 | AW42: =Z42*$O42 -> 0 | AX42: =AA42*$N42 -> 0 | AY42: =AA42*$O42 -> 0
B43: NU-06 | C43: Topsoil sieving | D43: ለም አፈር ማበጠር | E43: Soil & polytube | F43: m³ | G43: Industry average | H43: =IFERROR(INDEX('Benchmark Data'!$AC$7:$AC$130,MATCH($B43,'Benchmark Data'!$A$7:$A$130,0)),0) -> 0.5 | I43: =IFERROR(INDEX('Benchmark Data'!$AD$7:$AD$130,MATCH($B43,'Benchmark Data'!$A$7:$A$130,0)),0) -> 100 | J43: =H43*I43 -> 50 | L43: =IFERROR(INDEX('Benchmark Data'!$AE$7:$AE$130,MATCH($B43,'Benchmark Data'!$A$7:$A$130,0)),0) -> 1 | M43: =K43*L43 -> 0 | N43: =M43*H43 -> 0 | O43: =M43*J43 -> 0
B44: NU-06 | C44: Topsoil sieving | D44: ለም አፈር ማበጠር | E44: Soil & polytube | F44: m³ | G44: +25% | H44: =H43 -> 0.5 | I44: =I43*(1+Settings!$C$8) -> 125 | J44: =H44*I44 -> 62.5 | K44: =K43 -> 0 | L44: =L43 -> 1 | M44: =K44*L44 -> 0 | N44: =M44*H44 -> 0 | O44: =M44*J44 -> 0
B45: NU-06 | C45: Topsoil sieving | D45: ለም አፈር ማበጠር | E45: Soil & polytube | F45: m³ | G45: +50% | H45: =H43 -> 0.5 | I45: =I43*(1+Settings!$C$9) -> 150 | J45: =H45*I45 -> 75 | K45: =K43 -> 0 | L45: =L43 -> 1 | M45: =K45*L45 -> 0 | N45: =M45*H45 -> 0 | O45: =M45*J45 -> 0
...

Sheet Young Coffee
A1: Young Coffee – activity plan and budget
A2: ="Farm: "&Settings!$C$6&" | Plan year: "&Settings!$C$7 -> Farm: Chaka Buna Estate (Silva Forest Coffee) | Plan year: 2019 EFY (2026/27) – confirm
B3: Plan basis (drop-down) ► | C3: Industry average | D3: Sets the Chaka Buna plan row of every activity on this tab. Activities with no industry-average rate always use the Expert input row.
B5: GENERAL INFORMATION | F5: CATEGORY TOTALS
B6: Metric (English) | C6: Metric (Amharic) | D6: Unit | E6: Quantity | F6: Rate scenario | M6: Total man-days | N6: Total cost (birr) | O6: Plan phasing (% of cost) | AA6: Plan monthly totals
B7: Total trees (net area) | C7: የቡና እግር ብዛት (ቁጥር) | D7: no. | F7: Industry average | M7: =SUMIF($F$17:$F$91,"Industry average",M$17:M$91) -> 0 | N7: =SUMIF($F$17:$F$91,"Industry average",N$17:N$91) -> 0
B8: Gross area | C8: ጠቅላላ የማሳ ስፋት (ሄ/ር) | D8: ha | F8: +25% | M8: =SUMIF($F$17:$F$91,"+25%",M$17:M$91) -> 0 | N8: =SUMIF($F$17:$F$91,"+25%",N$17:N$91) -> 0
B9: Average trees per ha | C9: የቡና እግር አማካይ (ሄ/ር) | D9: trees/ha | E9: =IFERROR($E$7/$E$8,0) -> 0 | F9: +50% | M9: =SUMIF($F$17:$F$91,"+50%",M$17:M$91) -> 0 | N9: =SUMIF($F$17:$F$91,"+50%",N$17:N$91) -> 0
F10: Expert input | M10: =SUMIF($F$17:$F$91,"Expert input",M$17:M$91) -> 0 | N10: =SUMIF($F$17:$F$91,"Expert input",N$17:N$91) -> 0
F11: Chaka Buna plan – counts in Summary | M11: =SUMIF($F$17:$F$91,"Chaka Buna plan",M$17:M$91) -> 0 | N11: =SUMIF($F$17:$F$91,"Chaka Buna plan",N$17:N$91) -> 0 | O11: =IFERROR(AB11/$N$11,0) -> 0 | P11: =IFERROR(AD11/$N$11,0) -> 0 | Q11: =IFERROR(AF11/$N$11,0) -> 0 | R11: =IFERROR(AH11/$N$11,0) -> 0 | S11: =IFERROR(AJ11/$N$11,0) -> 0 | T11: =IFERROR(AL11/$N$11,0) -> 0 | U11: =IFERROR(AN11/$N$11,0) -> 0 | V11: =IFERROR(AP11/$N$11,0) -> 0 | W11: =IFERROR(AR11/$N$11,0) -> 0 | X11: =IFERROR(AT11/$N$11,0) -> 0 | Y11: =IFERROR(AV11/$N$11,0) -> 0 | Z11: =IFERROR(AX11/$N$11,0) -> 0 | AA11: =SUM(AA17:AA91) -> 0 | AB11: =SUM(AB17:AB91) -> 0 | AC11: =SUM(AC17:AC91) -> 0 | AD11: =SUM(AD17:AD91) -> 0 | AE11: =SUM(AE17:AE91) -> 0 | AF11: =SUM(AF17:AF91) -> 0 | AG11: =SUM(AG17:AG91) -> 0 | AH11: =SUM(AH17:AH91) -> 0 | ... AX11: =SUM(AX17:AX91) -> 0
A15: ACTIVITY | F15: RATE (cost per unit = man-days × wage) | J15: QUANTITY | L15: TOTALS (calculated) | O15: PHASING – % of annual (input on the Chaka Buna plan row) | AA15: MONTHLY MAN-DAYS AND COST (Chaka Buna plan row)
A16: Code | B16: Activity | C16: Activity (Amharic) | D16: Sub-group | E16: Unit | F16: Rate scenario | G16: Man-days per unit | H16: Wage per man-day (birr) | I16: Cost per unit (birr) | J16: Activity quantity per round | K16: Frequency (times / year) | L16: Total activity quantity | M16: Total man-days per activity | N16: Total cost per activity (birr) | O16: Tikimt (Oct) | P16: Hidar (Nov) | Q16: Tahsas (Dec) | R16: Tir (Jan) | S16: Yekatit (Feb) | T16: Megabit (Mar) | U16: Miyazya (Apr) | V16: Ginbot (May) | W16: Sene (Jun) | X16: Hamle (Jul) | Y16: Nehase (Aug) | Z16: Meskerem (Sep) | AA16: Tikimt (Oct) – man-days | AB16: Tikimt (Oct) – cost | AC16: Hidar (Nov) – man-days | AD16: Hidar (Nov) – cost | AE16: Tahsas (Dec) – man-days | AF16: Tahsas (Dec) – cost | AG16: Tir (Jan) – man-days | AH16: Tir (Jan) – cost | AI16: Yekatit (Feb) – man-days | AJ16: Yekatit (Feb) – cost | AK16: Megabit (Mar) – man-days | AL16: Megabit (Mar) – cost | AM16: Miyazya (Apr) – man-days | AN16: Miyazya (Apr) – cost | AO16: Ginbot (May) – man-days | AP16: Ginbot (May) – cost | AQ16: Sene (Jun) – man-days | AR16: Sene (Jun) – cost | AS16: Hamle (Jul) – man-days | AT16: Hamle (Jul) – cost | AU16: Nehase (Aug) – man-days | AV16: Nehase (Aug) – cost | AW16: Meskerem (Sep) – man-days | AX16: Meskerem (Sep) – cost
A17: YC-01 | B17: Manual weeding (slashing) | C17: አረም ቁጥጥር በገጀራ | D17: Weed & soil care | E17: ha | F17: Industry average | G17: =IFERROR(INDEX('Benchmark Data'!$AC$7:$AC$130,MATCH($A17,'Benchmark Data'!$A$7:$A$130,0)),0) -> 20 | H17: =IFERROR(INDEX('Benchmark Data'!$AD$7:$AD$130,MATCH($A17,'Benchmark Data'!$A$7:$A$130,0)),0) -> 200 | I17: =G17*H17 -> 4000 | J17: =$E$8 -> 0 | K17: =IFERROR(INDEX('Benchmark Data'!$AE$7:$AE$130,MATCH($A17,'Benchmark Data'!$A$7:$A$130,0)),0) -> 4 | L17: =J17*K17 -> 0 | M17: =L17*G17 -> 0 | N17: =L17*I17 -> 0
A18: YC-01 | B18: Manual weeding (slashing) | C18: አረም ቁጥጥር በገጀራ | D18: Weed & soil care | E18: ha | F18: +25% | G18: =G17 -> 20 | H18: =H17*(1+Settings!$C$8) -> 250 | I18: =G18*H18 -> 5000 | J18: =J17 -> 0 | K18: =K17 -> 4 | L18: =J18*K18 -> 0 | M18: =L18*G18 -> 0 | N18: =L18*I18 -> 0
A19: YC-01 | B19: Manual weeding (slashing) | C19: አረም ቁጥጥር በገጀራ | D19: Weed & soil care | E19: ha | F19: +50% | G19: =G17 -> 20 | H19: =H17*(1+Settings!$C$9) -> 300 | I19: =G19*H19 -> 6000 | J19: =J17 -> 0 | K19: =K17 -> 4 | L19: =J19*K19 -> 0 | M19: =L19*G19 -> 0 | N19: =L19*I19 -> 0
A20: YC-01 | B20: Manual weeding (slashing) | C20: አረም ቁጥጥር በገጀራ | D20: Weed & soil care | E20: ha | F20: Expert input | G20: =G17 -> 20 | H20: =H17 -> 200 | I20: =G20*H20 -> 4000 | J20: =J17 -> 0 | K20: =K17 -> 4 | L20: =J20*K20 -> 0 | M20: =L20*G20 -> 0 | N20: =L20*I20 -> 0
A21: YC-01 | B21: Manual weeding (slashing) | C21: አረም ቁጥጥር በገጀራ | D21: Weed & soil care | E21: ha | F21: Chaka Buna plan | G21: =CHOOSE(IF(OR($C$3="Expert input",$I$17=0),4,IF($C$3="+25%",2,IF($C$3="+50%",3,1))),G17,G18,G19,G20) -> 20 | H21: =CHOOSE(IF(OR($C$3="Expert input",$I$17=0),4,IF($C$3="+25%",2,IF($C$3="+50%",3,1))),H17,H18,H19,H20) -> 200 | I21: =G21*H21 -> 4000 | J21: =J17 -> 0 | K21: =CHOOSE(IF(OR($C$3="Expert input",$I$17=0),4,IF($C$3="+25%",2,IF($C$3="+50%",3,1))),K17,K18,K19,K20) -> 4 | L21: =J21*K21 -> 0 | M21: =L21*G21 -> 0 | N21: =L21*I21 -> 0 | O21: 0.25 | R21: 0.25 | V21: 0.25 | Y21: 0.25 | AA21: =O21*$M21 -> 0 | AB21: =O21*$N21 -> 0 | AC21: =P21*$M21 -> 0 | AD21: =P21*$N21 -> 0 | AE21: =Q21*$M21 -> 0 | AF21: =Q21*$N21 -> 0 | AG21: =R21*$M21 -> 0 | AH21: =R21*$N21 -> 0 | AI21: =S21*$M21 -> 0 | AJ21: =S21*$N21 -> 0 | AK21: =T21*$M21 -> 0 | AL21: =T21*$N21 -> 0 | AM21: =U21*$M21 -> 0 | AN21: =U21*$N21 -> 0 | AO21: =V21*$M21 -> 0 | AP21: =V21*$N21 -> 0 | AQ21: =W21*$M21 -> 0 | AR21: =W21*$N21 -> 0 | AS21: =X21*$M21 -> 0 | AT21: =X21*$N21 -> 0 | AU21: =Y21*$M21 -> 0 | AV21: =Y21*$N21 -> 0 | AW21: =Z21*$M21 -> 0 | AX21: =Z21*$N21 -> 0
A22: YC-02 | B22: Hoeing | C22: ኩትኳቶ | D22: Weed & soil care | E22: tree | F22: Industry average | G22: =IFERROR(INDEX('Benchmark Data'!$AC$7:$AC$130,MATCH($A22,'Benchmark Data'!$A$7:$A$130,0)),0) -> 0.0096666667 | H22: =IFERROR(INDEX('Benchmark Data'!$AD$7:$AD$130,MATCH($A22,'Benchmark Data'!$A$7:$A$130,0)),0) -> 168.96552 | I22: =G22*H22 -> 1.6333333 | J22: =$E$7 -> 0 | K22: =IFERROR(INDEX('Benchmark Data'!$AE$7:$AE$130,MATCH($A22,'Benchmark Data'!$A$7:$A$130,0)),0) -> 1 | L22: =J22*K22 -> 0 | M22: =L22*G22 -> 0 | N22: =L22*I22 -> 0
A23: YC-02 | B23: Hoeing | C23: ኩትኳቶ | D23: Weed & soil care | E23: tree | F23: +25% | G23: =G22 -> 0.0096666667 | H23: =H22*(1+Settings!$C$8) -> 211.2069 | I23: =G23*H23 -> 2.0416667 | J23: =J22 -> 0 | K23: =K22 -> 1 | L23: =J23*K23 -> 0 | M23: =L23*G23 -> 0 | N23: =L23*I23 -> 0
A24: YC-02 | B24: Hoeing | C24: ኩትኳቶ | D24: Weed & soil care | E24: tree | F24: +50% | G24: =G22 -> 0.0096666667 | H24: =H22*(1+Settings!$C$9) -> 253.44828 | I24: =G24*H24 -> 2.45 | J24: =J22 -> 0 | K24: =K22 -> 1 | L24: =J24*K24 -> 0 | M24: =L24*G24 -> 0 | N24: =L24*I24 -> 0
A25: YC-02 | B25: Hoeing | C25: ኩትኳቶ | D25: Weed & soil care | E25: tree | F25: Expert input | G25: =G22 -> 0.0096666667 | H25: =H22 -> 168.96552 | I25: =G25*H25 -> 1.6333333 | J25: =J22 -> 0 | K25: =K22 -> 1 | L25: =J25*K25 -> 0 | M25: =L25*G25 -> 0 | N25: =L25*I25 -> 0
A26: YC-02 | B26: Hoeing | C26: ኩትኳቶ | D26: Weed & soil care | E26: tree | F26: Chaka Buna plan | G26: =CHOOSE(IF(OR($C$3="Expert input",$I$22=0),4,IF($C$3="+25%",2,IF($C$3="+50%",3,1))),G22,G23,G24,G25) -> 0.0096666667 | H26: =CHOOSE(IF(OR($C$3="Expert input",$I$22=0),4,IF($C$3="+25%",2,IF($C$3="+50%",3,1))),H22,H23,H24,H25) -> 168.96552 | I26: =G26*H26 -> 1.6333333 | J26: =J22 -> 0 | K26: =CHOOSE(IF(OR($C$3="Expert input",$I$22=0),4,IF($C$3="+25%",2,IF($C$3="+50%",3,1))),K22,K23,K24,K25) -> 1 | L26: =J26*K26 -> 0 | M26: =L26*G26 -> 0 | N26: =L26*I26 -> 0 | P26: 0.17 | Q26: 0.17 | V26: 0.33 | X26: 0.33 | AA26: =O26*$M26 -> 0 | AB26: =O26*$N26 -> 0 | AC26: =P26*$M26 -> 0 | AD26: =P26*$N26 -> 0 | AE26: =Q26*$M26 -> 0 | AF26: =Q26*$N26 -> 0 | AG26: =R26*$M26 -> 0 | AH26: =R26*$N26 -> 0 | AI26: =S26*$M26 -> 0 | AJ26: =S26*$N26 -> 0 | AK26: =T26*$M26 -> 0 | AL26: =T26*$N26 -> 0 | AM26: =U26*$M26 -> 0 | AN26: =U26*$N26 -> 0 | AO26: =V26*$M26 -> 0 | AP26: =V26*$N26 -> 0 | AQ26: =W26*$M26 -> 0 | AR26: =W26*$N26 -> 0 | AS26: =X26*$M26 -> 0 | AT26: =X26*$N26 -> 0 | AU26: =Y26*$M26 -> 0 | AV26: =Y26*$N26 -> 0 | AW26: =Z26*$M26 -> 0 | AX26: =Z26*$N26 -> 0
A27: YC-03 | B27: Ring weeding | C27: ችግኝ ቡና ዙሪያ አረም | D27: Weed & soil care | E27: tree | F27: Industry average | G27: =IFERROR(INDEX('Benchmark Data'!$AC$7:$AC$130,MATCH($A27,'Benchmark Data'!$A$7:$A$130,0)),0) -> 0.0096666667 | H27: =IFERROR(INDEX('Benchmark Data'!$AD$7:$AD$130,MATCH($A27,'Benchmark Data'!$A$7:$A$130,0)),0) -> 134.48276 | I27: =G27*H27 -> 1.3 | J27: =$E$7 -> 0 | K27: =IFERROR(INDEX('Benchmark Data'!$AE$7:$AE$130,MATCH($A27,'Benchmark Data'!$A$7:$A$130,0)),0) -> 2 | L27: =J27*K27 -> 0 | M27: =L27*G27 -> 0 | N27: =L27*I27 -> 0
A28: YC-03 | B28: Ring weeding | C28: ችግኝ ቡና ዙሪያ አረም | D28: Weed & soil care | E28: tree | F28: +25% | G28: =G27 -> 0.0096666667 | H28: =H27*(1+Settings!$C$8) -> 168.10345 | I28: =G28*H28 -> 1.625 | J28: =J27 -> 0 | K28: =K27 -> 2 | L28: =J28*K28 -> 0 | M28: =L28*G28 -> 0 | N28: =L28*I28 -> 0
A29: YC-03 | B29: Ring weeding | C29: ችግኝ ቡና ዙሪያ አረም | D29: Weed & soil care | E29: tree | F29: +50% | G29: =G27 -> 0.0096666667 | H29: =H27*(1+Settings!$C$9) -> 201.72414 | I29: =G29*H29 -> 1.95 | J29: =J27 -> 0 | K29: =K27 -> 2 | L29: =J29*K29 -> 0 | M29: =L29*G29 -> 0 | N29: =L29*I29 -> 0
A30: YC-03 | B30: Ring weeding | C30: ችግኝ ቡና ዙሪያ አረም | D30: Weed & soil care | E30: tree | F30: Expert input | G30: =G27 -> 0.0096666667 | H30: =H27 -> 134.48276 | I30: =G30*H30 -> 1.3 | J30: =J27 -> 0 | K30: =K27 -> 2 | L30: =J30*K30 -> 0 | M30: =L30*G30 -> 0 | N30: =L30*I30 -> 0
A31: YC-03 | B31: Ring weeding | C31: ችግኝ ቡና ዙሪያ አረም | D31: Weed & soil care | E31: tree | F31: Chaka Buna plan | G31: =CHOOSE(IF(OR($C$3="Expert input",$I$27=0),4,IF($C$3="+25%",2,IF($C$3="+50%",3,1))),G27,G28,G29,G30) -> 0.0096666667 | H31: =CHOOSE(IF(OR($C$3="Expert input",$I$27=0),4,IF($C$3="+25%",2,IF($C$3="+50%",3,1))),H27,H28,H29,H30) -> 134.48276 | I31: =G31*H31 -> 1.3 | J31: =J27 -> 0 | K31: =CHOOSE(IF(OR($C$3="Expert input",$I$27=0),4,IF($C$3="+25%",2,IF($C$3="+50%",3,1))),K27,K28,K29,K30) -> 2 | L31: =J31*K31 -> 0 | M31: =L31*G31 -> 0 | N31: =L31*I31 -> 0 | O31: 0.17 | Q31: 0.17 | T31: 0.17 | X31: 0.17 | Z31: 0.32 | AA31: =O31*$M31 -> 0 | AB31: =O31*$N31 -> 0 | AC31: =P31*$M31 -> 0 | AD31: =P31*$N31 -> 0 | AE31: =Q31*$M31 -> 0 | AF31: =Q31*$N31 -> 0 | AG31: =R31*$M31 -> 0 | AH31: =R31*$N31 -> 0 | AI31: =S31*$M31 -> 0 | AJ31: =S31*$N31 -> 0 | AK31: =T31*$M31 -> 0 | AL31: =T31*$N31 -> 0 | AM31: =U31*$M31 -> 0 | AN31: =U31*$N31 -> 0 | AO31: =V31*$M31 -> 0 | AP31: =V31*$N31 -> 0 | AQ31: =W31*$M31 -> 0 | AR31: =W31*$N31 -> 0 | AS31: =X31*$M31 -> 0 | AT31: =X31*$N31 -> 0 | AU31: =Y31*$M31 -> 0 | AV31: =Y31*$N31 -> 0 | AW31: =Z31*$M31 -> 0 | AX31: =Z31*$N31 -> 0
A32: YC-04 | B32: Mulch application | C32: ችግኝ ቡና ጉዝጓዝ ማድረግ | D32: Weed & soil care | E32: tree | F32: Industry average | G32: =IFERROR(INDEX('Benchmark Data'!$AC$7:$AC$130,MATCH($A32,'Benchmark Data'!$A$7:$A$130,0)),0) -> 0.01 | H32: =IFERROR(INDEX('Benchmark Data'!$AD$7:$AD$130,MATCH($A32,'Benchmark Data'!$A$7:$A$130,0)),0) -> 120 | I32: =G32*H32 -> 1.2 | J32: =$E$7 -> 0 | K32: =IFERROR(INDEX('Benchmark Data'!$AE$7:$AE$130,MATCH($A32,'Benchmark Data'!$A$7:$A$130,0)),0) -> 1 | L32: =J32*K32 -> 0 | M32: =L32*G32 -> 0 | N32: =L32*I32 -> 0
A33: YC-04 | B33: Mulch application | C33: ችግኝ ቡና ጉዝጓዝ ማድረግ | D33: Weed & soil care | E33: tree | F33: +25% | G33: =G32 -> 0.01 | H33: =H32*(1+Settings!$C$8) -> 150 | I33: =G33*H33 -> 1.5 | J33: =J32 -> 0 | K33: =K32 -> 1 | L33: =J33*K33 -> 0 | M33: =L33*G33 -> 0 | N33: =L33*I33 -> 0
A34: YC-04 | B34: Mulch application | C34: ችግኝ ቡና ጉዝጓዝ ማድረግ | D34: Weed & soil care | E34: tree | F34: +50% | G34: =G32 -> 0.01 | H34: =H32*(1+Settings!$C$9) -> 180 | I34: =G34*H34 -> 1.8 | J34: =J32 -> 0 | K34: =K32 -> 1 | L34: =J34*K34 -> 0 | M34: =L34*G34 -> 0 | N34: =L34*I34 -> 0
A35: YC-04 | B35: Mulch application | C35: ችግኝ ቡና ጉዝጓዝ ማድረግ | D35: Weed & soil care | E35: tree | F35: Expert input | G35: =G32 -> 0.01 | H35: =H32 -> 120 | I35: =G35*H35 -> 1.2 | J35: =J32 -> 0 | K35: =K32 -> 1 | L35: =J35*K35 -> 0 | M35: =L35*G35 -> 0 | N35: =L35*I35 -> 0
A36: YC-04 | B36: Mulch application | C36: ችግኝ ቡና ጉዝጓዝ ማድረግ | D36: Weed & soil care | E36: tree | F36: Chaka Buna plan | G36: =CHOOSE(IF(OR($C$3="Expert input",$I$32=0),4,IF($C$3="+25%",2,IF($C$3="+50%",3,1))),G32,G33,G34,G35) -> 0.01 | H36: =CHOOSE(IF(OR($C$3="Expert input",$I$32=0),4,IF($C$3="+25%",2,IF($C$3="+50%",3,1))),H32,H33,H34,H35) -> 120 | I36: =G36*H36 -> 1.2 | J36: =J32 -> 0 | K36: =CHOOSE(IF(OR($C$3="Expert input",$I$32=0),4,IF($C$3="+25%",2,IF($C$3="+50%",3,1))),K32,K33,K34,K35) -> 1 | L36: =J36*K36 -> 0 | M36: =L36*G36 -> 0 | N36: =L36*I36 -> 0 | R36: 1 | AA36: =O36*$M36 -> 0 | AB36: =O36*$N36 -> 0 | AC36: =P36*$M36 -> 0 | AD36: =P36*$N36 -> 0 | AE36: =Q36*$M36 -> 0 | AF36: =Q36*$N36 -> 0 | AG36: =R36*$M36 -> 0 | AH36: =R36*$N36 -> 0 | AI36: =S36*$M36 -> 0 | AJ36: =S36*$N36 -> 0 | AK36: =T36*$M36 -> 0 | AL36: =T36*$N36 -> 0 | AM36: =U36*$M36 -> 0 | AN36: =U36*$N36 -> 0 | AO36: =V36*$M36 -> 0 | AP36: =V36*$N36 -> 0 | AQ36: =W36*$M36 -> 0 | AR36: =W36*$N36 -> 0 | AS36: =X36*$M36 -> 0 | AT36: =X36*$N36 -> 0 | AU36: =Y36*$M36 -> 0 | AV36: =Y36*$N36 -> 0 | AW36: =Z36*$M36 -> 0 | AX36: =Z36*$N36 -> 0
A37: YC-05 | B37: Full block digging | C37: ሙሉ ብሎክ ማስቆፈር | D37: Weed & soil care | E37: ha | F37: Industry average | G37: =IFERROR(INDEX('Benchmark Data'!$AC$7:$AC$130,MATCH($A37,'Benchmark Data'!$A$7:$A$130,0)),0) -> 0 | H37: =IFERROR(INDEX('Benchmark Data'!$AD$7:$AD$130,MATCH($A37,'Benchmark Data'!$A$7:$A$130,0)),0) -> 0 | I37: =G37*H37 -> 0 | K37: =IFERROR(INDEX('Benchmark Data'!$AE$7:$AE$130,MATCH($A37,'Benchmark Data'!$A$7:$A$130,0)),0) -> 1 | L37: =J37*K37 -> 0 | M37: =L37*G37 -> 0 | N37: =L37*I37 -> 0
A38: YC-05 | B38: Full block digging | C38: ሙሉ ብሎክ ማስቆፈር | D38: Weed & soil care | E38: ha | F38: +25% | G38: =G37 -> 0 | H38: =H37*(1+Settings!$C$8) -> 0 | I38: =G38*H38 -> 0 | J38: =J37 -> 0 | K38: =K37 -> 1 | L38: =J38*K38 -> 0 | M38: =L38*G38 -> 0 | N38: =L38*I38 -> 0
A39: YC-05 | B39: Full block digging | C39: ሙሉ ብሎክ ማስቆፈር | D39: Weed & soil care | E39: ha | F39: +50% | G39: =G37 -> 0 | H39: =H37*(1+Settings!$C$9) -> 0 | I39: =G39*H39 -> 0 | J39: =J37 -> 0 | K39: =K37 -> 1 | L39: =J39*K39 -> 0 | M39: =L39*G39 -> 0 | N39: =L39*I39 -> 0
A40: YC-05 | B40: Full block digging | C40: ሙሉ ብሎክ ማስቆፈር | D40: Weed & soil care | E40: ha | F40: Expert input | G40: =IFERROR(INDEX('Benchmark Data'!$AH$7:$AH$130,MATCH($A40,'Benchmark Data'!$A$7:$A$130,0)),0) -> 10 | H40: =IFERROR(INDEX('Benchmark Data'!$AI$7:$AI$130,MATCH($A40,'Benchmark Data'!$A$7:$A$130,0)),0) -> 800 | I40: =G40*H40 -> 8000 | J40: =J37 -> 0 | K40: =IFERROR(INDEX('Benchmark Data'!$AJ$7:$AJ$130,MATCH($A40,'Benchmark Data'!$A$7:$A$130,0)),0) -> 1 | L40: =J40*K40 -> 0 | M40: =L40*G40 -> 0 | N40: =L40*I40 -> 0
A41: YC-05 | B41: Full block digging | C41: ሙሉ ብሎክ ማስቆፈር | D41: Weed & soil care | E41: ha | F41: Chaka Buna plan | G41: =CHOOSE(IF(OR($C$3="Expert input",$I$37=0),4,IF($C$3="+25%",2,IF($C$3="+50%",3,1))),G37,G38,G39,G40) -> 10 | H41: =CHOOSE(IF(OR($C$3="Expert input",$I$37=0),4,IF($C$3="+25%",2,IF($C$3="+50%",3,1))),H37,H38,H39,H40) -> 800 | I41: =G41*H41 -> 8000 | J41: =J37 -> 0 | K41: =CHOOSE(IF(OR($C$3="Expert input",$I$37=0),4,IF($C$3="+25%",2,IF($C$3="+50%",3,1))),K37,K38,K39,K40) -> 1 | L41: =J41*K41 -> 0 | M41: =L41*G41 -> 0 | N41: =L41*I41 -> 0 | R41: 0.34 | S41: 0.33 | T41: 0.33 | AA41: =O41*$M41 -> 0 | AB41: =O41*$N41 -> 0 | AC41: =P41*$M41 -> 0 | AD41: =P41*$N41 -> 0 | AE41: =Q41*$M41 -> 0 | AF41: =Q41*$N41 -> 0 | AG41: =R41*$M41 -> 0 | AH41: =R41*$N41 -> 0 | AI41: =S41*$M41 -> 0 | AJ41: =S41*$N41 -> 0 | AK41: =T41*$M41 -> 0 | AL41: =T41*$N41 -> 0 | AM41: =U41*$M41 -> 0 | AN41: =U41*$N41 -> 0 | AO41: =V41*$M41 -> 0 | AP41: =V41*$N41 -> 0 | AQ41: =W41*$M41 -> 0 | AR41: =W41*$N41 -> 0 | AS41: =X41*$M41 -> 0 | AT41: =X41*$N41 -> 0 | AU41: =Y41*$M41 -> 0 | AV41: =Y41*$N41 -> 0 | AW41: =Z41*$M41 -> 0 | AX41: =Z41*$N41 -> 0
A42: YC-06 | B42: Fertiliser application | C42: ማዳበሪያ ማድረግ | D42: Nutrition | E42: tree | F42: Industry average | G42: =IFERROR(INDEX('Benchmark Data'!$AC$7:$AC$130,MATCH($A42,'Benchmark Data'!$A$7:$A$130,0)),0) -> 0.0095 | H42: =IFERROR(INDEX('Benchmark Data'!$AD$7:$AD$130,MATCH($A42,'Benchmark Data'!$A$7:$A$130,0)),0) -> 100 | I42: =G42*H42 -> 0.95 | J42: =$E$7 -> 0 | K42: =IFERROR(INDEX('Benchmark Data'!$AE$7:$AE$130,MATCH($A42,'Benchmark Data'!$A$7:$A$130,0)),0) -> 1 | L42: =J42*K42 -> 0 | M42: =L42*G42 -> 0 | N42: =L42*I42 -> 0
A43: YC-06 | B43: Fertiliser application | C43: ማዳበሪያ ማድረግ | D43: Nutrition | E43: tree | F43: +25% | G43: =G42 -> 0.0095 | H43: =H42*(1+Settings!$C$8) -> 125 | I43: =G43*H43 -> 1.1875 | J43: =J42 -> 0 | K43: =K42 -> 1 | L43: =J43*K43 -> 0 | M43: =L43*G43 -> 0 | N43: =L43*I43 -> 0
A44: YC-06 | B44: Fertiliser application | C44: ማዳበሪያ ማድረግ | D44: Nutrition | E44: tree | F44: +50% | G44: =G42 -> 0.0095 | H44: =H42*(1+Settings!$C$9) -> 150 | I44: =G44*H44 -> 1.425 | J44: =J42 -> 0 | K44: =K42 -> 1 | L44: =J44*K44 -> 0 | M44: =L44*G44 -> 0 | N44: =L44*I44 -> 0
...

Sheet Matured Coffee
A1: Matured Coffee – activity plan and budget
A2: ="Farm: "&Settings!$C$6&" | Plan year: "&Settings!$C$7 -> Farm: Chaka Buna Estate (Silva Forest Coffee) | Plan year: 2019 EFY (2026/27) – confirm
B3: Plan basis (drop-down) ► | C3: Industry average | D3: Sets the Chaka Buna plan row of every activity on this tab. Activities with no industry-average rate always use the Expert input row.
B5: GENERAL INFORMATION | F5: CATEGORY TOTALS
B6: Metric (English) | C6: Metric (Amharic) | D6: Unit | E6: Quantity | F6: Rate scenario | M6: Total man-days | N6: Total cost (birr) | O6: Plan phasing (% of cost) | AA6: Plan monthly totals
B7: Total coffee area | C7: ጠቅላላ የመሬት (ሄ/ር) | D7: ha | F7: Industry average | M7: =SUMIF($F$17:$F$191,"Industry average",M$17:M$191) -> 0 | N7: =SUMIF($F$17:$F$191,"Industry average",N$17:N$191) -> 0
B8: Total mature trees (net area) | C8: እናት ቡና እግር ብዛት (ቁጥር) | D8: no. | F8: +25% | M8: =SUMIF($F$17:$F$191,"+25%",M$17:M$191) -> 0 | N8: =SUMIF($F$17:$F$191,"+25%",N$17:N$191) -> 0
B9: Average trees per ha | C9: የቡና እግር አማካይ (ሄ/ር) | D9: trees/ha | E9: =IFERROR($E$8/$E$7,0) -> 0 | F9: +50% | M9: =SUMIF($F$17:$F$191,"+50%",M$17:M$191) -> 0 | N9: =SUMIF($F$17:$F$191,"+50%",N$17:N$191) -> 0
B10: Trees to stump | C10: የሚጎነደል ቡና | D10: no. | F10: Expert input | M10: =SUMIF($F$17:$F$191,"Expert input",M$17:M$191) -> 0 | N10: =SUMIF($F$17:$F$191,"Expert input",N$17:N$191) -> 0
F11: Chaka Buna plan – counts in Summary | M11: =SUMIF($F$17:$F$191,"Chaka Buna plan",M$17:M$191) -> 0 | N11: =SUMIF($F$17:$F$191,"Chaka Buna plan",N$17:N$191) -> 0 | O11: =IFERROR(AB11/$N$11,0) -> 0 | P11: =IFERROR(AD11/$N$11,0) -> 0 | Q11: =IFERROR(AF11/$N$11,0) -> 0 | R11: =IFERROR(AH11/$N$11,0) -> 0 | S11: =IFERROR(AJ11/$N$11,0) -> 0 | T11: =IFERROR(AL11/$N$11,0) -> 0 | U11: =IFERROR(AN11/$N$11,0) -> 0 | V11: =IFERROR(AP11/$N$11,0) -> 0 | W11: =IFERROR(AR11/$N$11,0) -> 0 | X11: =IFERROR(AT11/$N$11,0) -> 0 | Y11: =IFERROR(AV11/$N$11,0) -> 0 | Z11: =IFERROR(AX11/$N$11,0) -> 0 | AA11: =SUM(AA17:AA191) -> 0 | AB11: =SUM(AB17:AB191) -> 0 | AC11: =SUM(AC17:AC191) -> 0 | AD11: =SUM(AD17:AD191) -> 0 | AE11: =SUM(AE17:AE191) -> 0 | AF11: =SUM(AF17:AF191) -> 0 | AG11: =SUM(AG17:AG191) -> 0 | AH11: =SUM(AH17:AH191) -> 0 | ... AX11: =SUM(AX17:AX191) -> 0
A15: ACTIVITY | F15: RATE (cost per unit = man-days × wage) | J15: QUANTITY | L15: TOTALS (calculated) | O15: PHASING – % of annual (input on the Chaka Buna plan row) | AA15: MONTHLY MAN-DAYS AND COST (Chaka Buna plan row)
A16: Code | B16: Activity | C16: Activity (Amharic) | D16: Sub-group | E16: Unit | F16: Rate scenario | G16: Man-days per unit | H16: Wage per man-day (birr) | I16: Cost per unit (birr) | J16: Activity quantity per round | K16: Frequency (times / year) | L16: Total activity quantity | M16: Total man-days per activity | N16: Total cost per activity (birr) | O16: Tikimt (Oct) | P16: Hidar (Nov) | Q16: Tahsas (Dec) | R16: Tir (Jan) | S16: Yekatit (Feb) | T16: Megabit (Mar) | U16: Miyazya (Apr) | V16: Ginbot (May) | W16: Sene (Jun) | X16: Hamle (Jul) | Y16: Nehase (Aug) | Z16: Meskerem (Sep) | AA16: Tikimt (Oct) – man-days | AB16: Tikimt (Oct) – cost | AC16: Hidar (Nov) – man-days | AD16: Hidar (Nov) – cost | AE16: Tahsas (Dec) – man-days | AF16: Tahsas (Dec) – cost | AG16: Tir (Jan) – man-days | AH16: Tir (Jan) – cost | AI16: Yekatit (Feb) – man-days | AJ16: Yekatit (Feb) – cost | AK16: Megabit (Mar) – man-days | AL16: Megabit (Mar) – cost | AM16: Miyazya (Apr) – man-days | AN16: Miyazya (Apr) – cost | AO16: Ginbot (May) – man-days | AP16: Ginbot (May) – cost | AQ16: Sene (Jun) – man-days | AR16: Sene (Jun) – cost | AS16: Hamle (Jul) – man-days | AT16: Hamle (Jul) – cost | AU16: Nehase (Aug) – man-days | AV16: Nehase (Aug) – cost | AW16: Meskerem (Sep) – man-days | AX16: Meskerem (Sep) – cost
A17: MC-01 | B17: Manual weeding (slashing) | C17: አረም ቁጥጥር በገጀራ | D17: Weed control | E17: ha | F17: Industry average | G17: =IFERROR(INDEX('Benchmark Data'!$AC$7:$AC$130,MATCH($A17,'Benchmark Data'!$A$7:$A$130,0)),0) -> 20 | H17: =IFERROR(INDEX('Benchmark Data'!$AD$7:$AD$130,MATCH($A17,'Benchmark Data'!$A$7:$A$130,0)),0) -> 200 | I17: =G17*H17 -> 4000 | J17: =$E$7 -> 0 | K17: =IFERROR(INDEX('Benchmark Data'!$AE$7:$AE$130,MATCH($A17,'Benchmark Data'!$A$7:$A$130,0)),0) -> 3 | L17: =J17*K17 -> 0 | M17: =L17*G17 -> 0 | N17: =L17*I17 -> 0
A18: MC-01 | B18: Manual weeding (slashing) | C18: አረም ቁጥጥር በገጀራ | D18: Weed control | E18: ha | F18: +25% | G18: =G17 -> 20 | H18: =H17*(1+Settings!$C$8) -> 250 | I18: =G18*H18 -> 5000 | J18: =J17 -> 0 | K18: =K17 -> 3 | L18: =J18*K18 -> 0 | M18: =L18*G18 -> 0 | N18: =L18*I18 -> 0
A19: MC-01 | B19: Manual weeding (slashing) | C19: አረም ቁጥጥር በገጀራ | D19: Weed control | E19: ha | F19: +50% | G19: =G17 -> 20 | H19: =H17*(1+Settings!$C$9) -> 300 | I19: =G19*H19 -> 6000 | J19: =J17 -> 0 | K19: =K17 -> 3 | L19: =J19*K19 -> 0 | M19: =L19*G19 -> 0 | N19: =L19*I19 -> 0
A20: MC-01 | B20: Manual weeding (slashing) | C20: አረም ቁጥጥር በገጀራ | D20: Weed control | E20: ha | F20: Expert input | G20: =G17 -> 20 | H20: =H17 -> 200 | I20: =G20*H20 -> 4000 | J20: =J17 -> 0 | K20: =K17 -> 3 | L20: =J20*K20 -> 0 | M20: =L20*G20 -> 0 | N20: =L20*I20 -> 0
A21: MC-01 | B21: Manual weeding (slashing) | C21: አረም ቁጥጥር በገጀራ | D21: Weed control | E21: ha | F21: Chaka Buna plan | G21: =CHOOSE(IF(OR($C$3="Expert input",$I$17=0),4,IF($C$3="+25%",2,IF($C$3="+50%",3,1))),G17,G18,G19,G20) -> 20 | H21: =CHOOSE(IF(OR($C$3="Expert input",$I$17=0),4,IF($C$3="+25%",2,IF($C$3="+50%",3,1))),H17,H18,H19,H20) -> 200 | I21: =G21*H21 -> 4000 | J21: =J17 -> 0 | K21: =CHOOSE(IF(OR($C$3="Expert input",$I$17=0),4,IF($C$3="+25%",2,IF($C$3="+50%",3,1))),K17,K18,K19,K20) -> 3 | L21: =J21*K21 -> 0 | M21: =L21*G21 -> 0 | N21: =L21*I21 -> 0 | Q21: 0.14 | R21: 0.02 | S21: 0.15 | T21: 0.13 | U21: 0.05 | V21: 0.15 | W21: 0.04 | X21: 0.15 | Y21: 0.04 | Z21: 0.13 | AA21: =O21*$M21 -> 0 | AB21: =O21*$N21 -> 0 | AC21: =P21*$M21 -> 0 | AD21: =P21*$N21 -> 0 | AE21: =Q21*$M21 -> 0 | AF21: =Q21*$N21 -> 0 | AG21: =R21*$M21 -> 0 | AH21: =R21*$N21 -> 0 | AI21: =S21*$M21 -> 0 | AJ21: =S21*$N21 -> 0 | AK21: =T21*$M21 -> 0 | AL21: =T21*$N21 -> 0 | AM21: =U21*$M21 -> 0 | AN21: =U21*$N21 -> 0 | AO21: =V21*$M21 -> 0 | AP21: =V21*$N21 -> 0 | AQ21: =W21*$M21 -> 0 | AR21: =W21*$N21 -> 0 | AS21: =X21*$M21 -> 0 | AT21: =X21*$N21 -> 0 | AU21: =Y21*$M21 -> 0 | AV21: =Y21*$N21 -> 0 | AW21: =Z21*$M21 -> 0 | AX21: =Z21*$N21 -> 0
A22: MC-02 | B22: Chemical weeding | C22: ፀረ-አረም መድሃኒት ርጭት | D22: Weed control | E22: ha | F22: Industry average | G22: =IFERROR(INDEX('Benchmark Data'!$AC$7:$AC$130,MATCH($A22,'Benchmark Data'!$A$7:$A$130,0)),0) -> 3.4444444 | H22: =IFERROR(INDEX('Benchmark Data'!$AD$7:$AD$130,MATCH($A22,'Benchmark Data'!$A$7:$A$130,0)),0) -> 240 | I22: =G22*H22 -> 826.66667 | K22: =IFERROR(INDEX('Benchmark Data'!$AE$7:$AE$130,MATCH($A22,'Benchmark Data'!$A$7:$A$130,0)),0) -> 2 | L22: =J22*K22 -> 0 | M22: =L22*G22 -> 0 | N22: =L22*I22 -> 0
A23: MC-02 | B23: Chemical weeding | C23: ፀረ-አረም መድሃኒት ርጭት | D23: Weed control | E23: ha | F23: +25% | G23: =G22 -> 3.4444444 | H23: =H22*(1+Settings!$C$8) -> 300 | I23: =G23*H23 -> 1033.3333 | J23: =J22 -> 0 | K23: =K22 -> 2 | L23: =J23*K23 -> 0 | M23: =L23*G23 -> 0 | N23: =L23*I23 -> 0
A24: MC-02 | B24: Chemical weeding | C24: ፀረ-አረም መድሃኒት ርጭት | D24: Weed control | E24: ha | F24: +50% | G24: =G22 -> 3.4444444 | H24: =H22*(1+Settings!$C$9) -> 360 | I24: =G24*H24 -> 1240 | J24: =J22 -> 0 | K24: =K22 -> 2 | L24: =J24*K24 -> 0 | M24: =L24*G24 -> 0 | N24: =L24*I24 -> 0
A25: MC-02 | B25: Chemical weeding | C25: ፀረ-አረም መድሃኒት ርጭት | D25: Weed control | E25: ha | F25: Expert input | G25: =G22 -> 3.4444444 | H25: =H22 -> 240 | I25: =G25*H25 -> 826.66667 | J25: =J22 -> 0 | K25: =K22 -> 2 | L25: =J25*K25 -> 0 | M25: =L25*G25 -> 0 | N25: =L25*I25 -> 0
A26: MC-02 | B26: Chemical weeding | C26: ፀረ-አረም መድሃኒት ርጭት | D26: Weed control | E26: ha | F26: Chaka Buna plan | G26: =CHOOSE(IF(OR($C$3="Expert input",$I$22=0),4,IF($C$3="+25%",2,IF($C$3="+50%",3,1))),G22,G23,G24,G25) -> 3.4444444 | H26: =CHOOSE(IF(OR($C$3="Expert input",$I$22=0),4,IF($C$3="+25%",2,IF($C$3="+50%",3,1))),H22,H23,H24,H25) -> 240 | I26: =G26*H26 -> 826.66667 | J26: =J22 -> 0 | K26: =CHOOSE(IF(OR($C$3="Expert input",$I$22=0),4,IF($C$3="+25%",2,IF($C$3="+50%",3,1))),K22,K23,K24,K25) -> 2 | L26: =J26*K26 -> 0 | M26: =L26*G26 -> 0 | N26: =L26*I26 -> 0 | O26: 0.22 | T26: 0.09 | U26: 0.05 | V26: 0.17 | W26: 0.07 | Y26: 0.23 | Z26: 0.17 | AA26: =O26*$M26 -> 0 | AB26: =O26*$N26 -> 0 | AC26: =P26*$M26 -> 0 | AD26: =P26*$N26 -> 0 | AE26: =Q26*$M26 -> 0 | AF26: =Q26*$N26 -> 0 | AG26: =R26*$M26 -> 0 | AH26: =R26*$N26 -> 0 | AI26: =S26*$M26 -> 0 | AJ26: =S26*$N26 -> 0 | AK26: =T26*$M26 -> 0 | AL26: =T26*$N26 -> 0 | AM26: =U26*$M26 -> 0 | AN26: =U26*$N26 -> 0 | AO26: =V26*$M26 -> 0 | AP26: =V26*$N26 -> 0 | AQ26: =W26*$M26 -> 0 | AR26: =W26*$N26 -> 0 | AS26: =X26*$M26 -> 0 | AT26: =X26*$N26 -> 0 | AU26: =Y26*$M26 -> 0 | AV26: =Y26*$N26 -> 0 | AW26: =Z26*$M26 -> 0 | AX26: =Z26*$N26 -> 0
A27: MC-03 | B27: Water fetching for spraying | C27: ለፀረ-አረም መድሃኒት ውሃ መቅዳት | D27: Weed control | E27: knapsack | F27: Industry average | G27: =IFERROR(INDEX('Benchmark Data'!$AC$7:$AC$130,MATCH($A27,'Benchmark Data'!$A$7:$A$130,0)),0) -> 0.22222222 | H27: =IFERROR(INDEX('Benchmark Data'!$AD$7:$AD$130,MATCH($A27,'Benchmark Data'!$A$7:$A$130,0)),0) -> 120 | I27: =G27*H27 -> 26.666667 | K27: =IFERROR(INDEX('Benchmark Data'!$AE$7:$AE$130,MATCH($A27,'Benchmark Data'!$A$7:$A$130,0)),0) -> 2 | L27: =J27*K27 -> 0 | M27: =L27*G27 -> 0 | N27: =L27*I27 -> 0
A28: MC-03 | B28: Water fetching for spraying | C28: ለፀረ-አረም መድሃኒት ውሃ መቅዳት | D28: Weed control | E28: knapsack | F28: +25% | G28: =G27 -> 0.22222222 | H28: =H27*(1+Settings!$C$8) -> 150 | I28: =G28*H28 -> 33.333333 | J28: =J27 -> 0 | K28: =K27 -> 2 | L28: =J28*K28 -> 0 | M28: =L28*G28 -> 0 | N28: =L28*I28 -> 0
A29: MC-03 | B29: Water fetching for spraying | C29: ለፀረ-አረም መድሃኒት ውሃ መቅዳት | D29: Weed control | E29: knapsack | F29: +50% | G29: =G27 -> 0.22222222 | H29: =H27*(1+Settings!$C$9) -> 180 | I29: =G29*H29 -> 40 | J29: =J27 -> 0 | K29: =K27 -> 2 | L29: =J29*K29 -> 0 | M29: =L29*G29 -> 0 | N29: =L29*I29 -> 0
A30: MC-03 | B30: Water fetching for spraying | C30: ለፀረ-አረም መድሃኒት ውሃ መቅዳት | D30: Weed control | E30: knapsack | F30: Expert input | G30: =G27 -> 0.22222222 | H30: =H27 -> 120 | I30: =G30*H30 -> 26.666667 | J30: =J27 -> 0 | K30: =K27 -> 2 | L30: =J30*K30 -> 0 | M30: =L30*G30 -> 0 | N30: =L30*I30 -> 0
A31: MC-03 | B31: Water fetching for spraying | C31: ለፀረ-አረም መድሃኒት ውሃ መቅዳት | D31: Weed control | E31: knapsack | F31: Chaka Buna plan | G31: =CHOOSE(IF(OR($C$3="Expert input",$I$27=0),4,IF($C$3="+25%",2,IF($C$3="+50%",3,1))),G27,G28,G29,G30) -> 0.22222222 | H31: =CHOOSE(IF(OR($C$3="Expert input",$I$27=0),4,IF($C$3="+25%",2,IF($C$3="+50%",3,1))),H27,H28,H29,H30) -> 120 | I31: =G31*H31 -> 26.666667 | J31: =J27 -> 0 | K31: =CHOOSE(IF(OR($C$3="Expert input",$I$27=0),4,IF($C$3="+25%",2,IF($C$3="+50%",3,1))),K27,K28,K29,K30) -> 2 | L31: =J31*K31 -> 0 | M31: =L31*G31 -> 0 | N31: =L31*I31 -> 0 | O31: 0.22 | T31: 0.09 | U31: 0.05 | V31: 0.17 | W31: 0.07 | Y31: 0.23 | Z31: 0.17 | AA31: =O31*$M31 -> 0 | AB31: =O31*$N31 -> 0 | AC31: =P31*$M31 -> 0 | AD31: =P31*$N31 -> 0 | AE31: =Q31*$M31 -> 0 | AF31: =Q31*$N31 -> 0 | AG31: =R31*$M31 -> 0 | AH31: =R31*$N31 -> 0 | AI31: =S31*$M31 -> 0 | AJ31: =S31*$N31 -> 0 | AK31: =T31*$M31 -> 0 | AL31: =T31*$N31 -> 0 | AM31: =U31*$M31 -> 0 | AN31: =U31*$N31 -> 0 | AO31: =V31*$M31 -> 0 | AP31: =V31*$N31 -> 0 | AQ31: =W31*$M31 -> 0 | AR31: =W31*$N31 -> 0 | AS31: =X31*$M31 -> 0 | AT31: =X31*$N31 -> 0 | AU31: =Y31*$M31 -> 0 | AV31: =Y31*$N31 -> 0 | AW31: =Z31*$M31 -> 0 | AX31: =Z31*$N31 -> 0
A32: MC-04 | B32: Ring weeding for fertiliser | C32: ለማዳበሪያ ዙሪያ ማውጣት | D32: Nutrition | E32: tree | F32: Industry average | G32: =IFERROR(INDEX('Benchmark Data'!$AC$7:$AC$130,MATCH($A32,'Benchmark Data'!$A$7:$A$130,0)),0) -> 0.01 | H32: =IFERROR(INDEX('Benchmark Data'!$AD$7:$AD$130,MATCH($A32,'Benchmark Data'!$A$7:$A$130,0)),0) -> 100 | I32: =G32*H32 -> 1 | J32: =$E$8 -> 0 | K32: =IFERROR(INDEX('Benchmark Data'!$AE$7:$AE$130,MATCH($A32,'Benchmark Data'!$A$7:$A$130,0)),0) -> 1 | L32: =J32*K32 -> 0 | M32: =L32*G32 -> 0 | N32: =L32*I32 -> 0
A33: MC-04 | B33: Ring weeding for fertiliser | C33: ለማዳበሪያ ዙሪያ ማውጣት | D33: Nutrition | E33: tree | F33: +25% | G33: =G32 -> 0.01 | H33: =H32*(1+Settings!$C$8) -> 125 | I33: =G33*H33 -> 1.25 | J33: =J32 -> 0 | K33: =K32 -> 1 | L33: =J33*K33 -> 0 | M33: =L33*G33 -> 0 | N33: =L33*I33 -> 0
A34: MC-04 | B34: Ring weeding for fertiliser | C34: ለማዳበሪያ ዙሪያ ማውጣት | D34: Nutrition | E34: tree | F34: +50% | G34: =G32 -> 0.01 | H34: =H32*(1+Settings!$C$9) -> 150 | I34: =G34*H34 -> 1.5 | J34: =J32 -> 0 | K34: =K32 -> 1 | L34: =J34*K34 -> 0 | M34: =L34*G34 -> 0 | N34: =L34*I34 -> 0
A35: MC-04 | B35: Ring weeding for fertiliser | C35: ለማዳበሪያ ዙሪያ ማውጣት | D35: Nutrition | E35: tree | F35: Expert input | G35: =G32 -> 0.01 | H35: =H32 -> 100 | I35: =G35*H35 -> 1 | J35: =J32 -> 0 | K35: =K32 -> 1 | L35: =J35*K35 -> 0 | M35: =L35*G35 -> 0 | N35: =L35*I35 -> 0
A36: MC-04 | B36: Ring weeding for fertiliser | C36: ለማዳበሪያ ዙሪያ ማውጣት | D36: Nutrition | E36: tree | F36: Chaka Buna plan | G36: =CHOOSE(IF(OR($C$3="Expert input",$I$32=0),4,IF($C$3="+25%",2,IF($C$3="+50%",3,1))),G32,G33,G34,G35) -> 0.01 | H36: =CHOOSE(IF(OR($C$3="Expert input",$I$32=0),4,IF($C$3="+25%",2,IF($C$3="+50%",3,1))),H32,H33,H34,H35) -> 100 | I36: =G36*H36 -> 1 | J36: =J32 -> 0 | K36: =CHOOSE(IF(OR($C$3="Expert input",$I$32=0),4,IF($C$3="+25%",2,IF($C$3="+50%",3,1))),K32,K33,K34,K35) -> 1 | L36: =J36*K36 -> 0 | M36: =L36*G36 -> 0 | N36: =L36*I36 -> 0 | U36: 0.17 | V36: 0.39 | W36: 0.11 | X36: 0.22 | Y36: 0.11 | AA36: =O36*$M36 -> 0 | AB36: =O36*$N36 -> 0 | AC36: =P36*$M36 -> 0 | AD36: =P36*$N36 -> 0 | AE36: =Q36*$M36 -> 0 | AF36: =Q36*$N36 -> 0 | AG36: =R36*$M36 -> 0 | AH36: =R36*$N36 -> 0 | AI36: =S36*$M36 -> 0 | AJ36: =S36*$N36 -> 0 | AK36: =T36*$M36 -> 0 | AL36: =T36*$N36 -> 0 | AM36: =U36*$M36 -> 0 | AN36: =U36*$N36 -> 0 | AO36: =V36*$M36 -> 0 | AP36: =V36*$N36 -> 0 | AQ36: =W36*$M36 -> 0 | AR36: =W36*$N36 -> 0 | AS36: =X36*$M36 -> 0 | AT36: =X36*$N36 -> 0 | AU36: =Y36*$M36 -> 0 | AV36: =Y36*$N36 -> 0 | AW36: =Z36*$M36 -> 0 | AX36: =Z36*$N36 -> 0
A37: MC-05 | B37: Fertiliser application | C37: ማዳበሪያ ማድረግ | D37: Nutrition | E37: tree | F37: Industry average | G37: =IFERROR(INDEX('Benchmark Data'!$AC$7:$AC$130,MATCH($A37,'Benchmark Data'!$A$7:$A$130,0)),0) -> 0.01 | H37: =IFERROR(INDEX('Benchmark Data'!$AD$7:$AD$130,MATCH($A37,'Benchmark Data'!$A$7:$A$130,0)),0) -> 96.666667 | I37: =G37*H37 -> 0.96666667 | J37: =$E$8 -> 0 | K37: =IFERROR(INDEX('Benchmark Data'!$AE$7:$AE$130,MATCH($A37,'Benchmark Data'!$A$7:$A$130,0)),0) -> 1 | L37: =J37*K37 -> 0 | M37: =L37*G37 -> 0 | N37: =L37*I37 -> 0
