Workbook

Sheet README
B2: Cropfort — Coffee Field OS Template (Plain, Farm-Agnostic)
B4: Purpose
B5: This is Cropfort's own standard operating template — blank, reusable for any farm on the platform. It is not specific to any owner, manager, or field operator; those identities are filled in when the template is instantiated for a real farm. The activity taxonomy (Tier 1 Core / Tier 2 Projects / Tier 3 Interventions) is Cropfort's own product standard and stays in the template as-is.
B7: Sheet Map, in the order they are used
B8: Activity List
B9: The full activity taxonomy, tier-tagged. Add, edit or re-tier activities here — every other sheet reads from this.
B10: Master
B11: Farm name, Term Start Date (drives every date on the workbook), and the block registry — hectares, variety, planting date, tree count. Fill this in first.
B12: Benchmark Rate Survey
B13: Two-adjacent-farm rate survey per activity. Lock the survey once entered; the average shows as a light-shade recommendation; override it and route for approval by the mandated person at the owning company. Approved rates feed the Labor Rate Card directly.
B14: Labor Rate Card
B15: Final piece rate per activity: Benchmark Approved Rate if one exists, otherwise mandays-norm x wage rate entered directly.
... B51: 4. The Monthly Client Report's narrative fields are placeholders for a person (or an AI drafting pass a person reviews) to fill in — the sheet does not write prose on its own.

Sheet Activity List
A1: Activity ID | B1: Tier | C1: Category | D1: Activity Name | E1: Unit of Measure | F1: Source / Notes | G1: Default Tick
A2: T1-001 | B2: Tier 1 — Core Services | C2: Nursery | D2: Land Clearing | E2: ha | F2: Cropfort Core Services standard | G2: Y
A3: T1-002 | B3: Tier 1 — Core Services | C3: Nursery | D3: Tree Felling | E3: ha | F3: Cropfort Core Services standard | G3: Y
A4: T1-003 | B4: Tier 1 — Core Services | C4: Nursery | D4: Soil Heaping | E4: m3 | F4: Cropfort Core Services standard | G4: Y
A5: T1-004 | B5: Tier 1 — Core Services | C5: Nursery | D5: Polytube Cutting | E5: kg | F5: Cropfort Core Services standard | G5: Y
A6: T1-005 | B6: Tier 1 — Core Services | C6: Nursery | D6: Polytube Filling | E6: seedling | F6: Cropfort Core Services standard | G6: Y
A7: T1-006 | B7: Tier 1 — Core Services | C7: Nursery | D7: Seedbed Preparation | E7: bed | F7: Cropfort Core Services standard | G7: Y
A8: T1-007 | B8: Tier 1 — Core Services | C8: Nursery | D8: Polytube Arranging | E8: bed | F8: Cropfort Core Services standard | G8: Y
A9: T1-008 | B9: Tier 1 — Core Services | C9: Nursery | D9: Seed Sowing | E9: bed | F9: Cropfort Core Services standard | G9: Y
A10: T1-009 | B10: Tier 1 — Core Services | C10: Nursery | D10: Mulch Material Preparation | E10: bed | F10: Cropfort Core Services standard | G10: Y
A11: T1-010 | B11: Tier 1 — Core Services | C11: Nursery | D11: Mulch Application | E11: bed | F11: Cropfort Core Services standard | G11: Y
A12: T1-011 | B12: Tier 1 — Core Services | C12: Nursery | D12: Shade Material Preparation | E12: bed | F12: Cropfort Core Services standard | G12: Y
... A135: T3-035 | B135: Tier 3 — Interventions | C135: B. Technical and Laboratory Services | D135: Buyer Hosting at SpiralLabs | E135: event | F135: Cropfort Interventions standard | G135: N

Sheet Master
A1: Master — Farm and Block Registry
A2: Farm Name:
A3: Term Start Date (Year 1, Month 1): | E3: All Annual Election windows and the per-block Calendar are calculated from this one date — set it once and everything downstream follows.
A5: Block ID | B5: Block Name | C5: Hectares | D5: Variety Planted | E5: Planting Date | F5: Tree Count | G5: Status | H5: Notes
H6: Add one row per block. Each block also needs its own Calendar tab, generated to match.
A13: This is the Cropfort platform template — blank on purpose. Every field here is filled in when the template is instantiated for a real farm. Adding a block row does not, on its own, create that block's Calendar tab or its Annual Election rows; those are generated to match whenever a block is added.

Sheet Benchmark Rate Survey
A1: Benchmark Rate Survey — Annual
A2: Survey the piece rate paid for each activity at two adjacent farms, lock it in once entered, and let that guide — but not dictate — this farm's own rate. The recommended rate is the plain average, shown in light shade; override it in the Proposed Rate column. Nothing is binding until the mandated approver for this farm's owning company signs off, after which the rate is locked for the year.
A4: Activity ID | B4: Activity Name | C4: Unit | D4: Neighbor Farm 1 (Name) | E4: Neighbor Farm 1 Rate (ETB/unit) | F4: Neighbor Farm 2 (Name) | G4: Neighbor Farm 2 Rate (ETB/unit) | H4: Survey Locked (Y/N) | I4: Recommended Rate (avg, light shade) | J4: Proposed Rate (override) | K4: Status | L4: Approver Name | M4: Approval Date | N4: Valid Until | O4: Approved Rate
A5: ='Activity List'!A2 -> T1-001 | B5: ='Activity List'!D2 -> Land Clearing | C5: ='Activity List'!E2 -> ha | H5: N | I5: =IFERROR(AVERAGE(E5,G5),"") | J5: =I5 | K5: Draft | N5: =IF(M5="","",EDATE(M5,12)) | O5: =IF(K5="Approved",J5,"")
A6: ='Activity List'!A3 -> T1-002 | B6: ='Activity List'!D3 -> Tree Felling | C6: ='Activity List'!E3 -> ha | H6: N | I6: =IFERROR(AVERAGE(E6,G6),"") | J6: =I6 | K6: Draft | N6: =IF(M6="","",EDATE(M6,12)) | O6: =IF(K6="Approved",J6,"")
A7: ='Activity List'!A4 -> T1-003 | B7: ='Activity List'!D4 -> Soil Heaping | C7: ='Activity List'!E4 -> m3 | H7: N | I7: =IFERROR(AVERAGE(E7,G7),"") | J7: =I7 | K7: Draft | N7: =IF(M7="","",EDATE(M7,12)) | O7: =IF(K7="Approved",J7,"")
A8: ='Activity List'!A5 -> T1-004 | B8: ='Activity List'!D5 -> Polytube Cutting | C8: ='Activity List'!E5 -> kg | H8: N | I8: =IFERROR(AVERAGE(E8,G8),"") | J8: =I8 | K8: Draft | N8: =IF(M8="","",EDATE(M8,12)) | O8: =IF(K8="Approved",J8,"")
A9: ='Activity List'!A6 -> T1-005 | B9: ='Activity List'!D6 -> Polytube Filling | C9: ='Activity List'!E6 -> seedling | H9: N | I9: =IFERROR(AVERAGE(E9,G9),"") | J9: =I9 | K9: Draft | N9: =IF(M9="","",EDATE(M9,12)) | O9: =IF(K9="Approved",J9,"")
A10: ='Activity List'!A7 -> T1-006 | B10: ='Activity List'!D7 -> Seedbed Preparation | C10: ='Activity List'!E7 -> bed | H10: N | I10: =IFERROR(AVERAGE(E10,G10),"") | J10: =I10 | K10: Draft | N10: =IF(M10="","",EDATE(M10,12)) | O10: =IF(K10="Approved",J10,"")
A11: ='Activity List'!A8 -> T1-007 | B11: ='Activity List'!D8 -> Polytube Arranging | C11: ='Activity List'!E8 -> bed | H11: N | I11: =IFERROR(AVERAGE(E11,G11),"") | J11: =I11 | K11: Draft | N11: =IF(M11="","",EDATE(M11,12)) | O11: =IF(K11="Approved",J11,"")
A12: ='Activity List'!A9 -> T1-008 | B12: ='Activity List'!D9 -> Seed Sowing | C12: ='Activity List'!E9 -> bed | H12: N | I12: =IFERROR(AVERAGE(E12,G12),"") | J12: =I12 | K12: Draft | N12: =IF(M12="","",EDATE(M12,12)) | O12: =IF(K12="Approved",J12,"")
A13: ='Activity List'!A10 -> T1-009 | B13: ='Activity List'!D10 -> Mulch Material Preparation | C13: ='Activity List'!E10 -> bed | H13: N | I13: =IFERROR(AVERAGE(E13,G13),"") | J13: =I13 | K13: Draft | N13: =IF(M13="","",EDATE(M13,12)) | O13: =IF(K13="Approved",J13,"")
A14: ='Activity List'!A11 -> T1-010 | B14: ='Activity List'!D11 -> Mulch Application | C14: ='Activity List'!E11 -> bed | H14: N | I14: =IFERROR(AVERAGE(E14,G14),"") | J14: =I14 | K14: Draft | N14: =IF(M14="","",EDATE(M14,12)) | O14: =IF(K14="Approved",J14,"")
A15: ='Activity List'!A12 -> T1-011 | B15: ='Activity List'!D12 -> Shade Material Preparation | C15: ='Activity List'!E12 -> bed | H15: N | I15: =IFERROR(AVERAGE(E15,G15),"") | J15: =I15 | K15: Draft | N15: =IF(M15="","",EDATE(M15,12)) | O15: =IF(K15="Approved",J15,"")
A16: ='Activity List'!A13 -> T1-012 | B16: ='Activity List'!D13 -> Shade Construction | C16: ='Activity List'!E13 -> bed | H16: N | I16: =IFERROR(AVERAGE(E16,G16),"") | J16: =I16 | K16: Draft | N16: =IF(M16="","",EDATE(M16,12)) | O16: =IF(K16="Approved",J16,"")
... A138: ='Activity List'!A135 -> T3-035 | B138: ='Activity List'!D135 -> Buyer Hosting at SpiralLabs | C138: ='Activity List'!E135 -> event | H138: N | I138: =IFERROR(AVERAGE(E138,G138),"") | J138: =I138 | K138: Draft | N138: =IF(M138="","",EDATE(M138,12)) | O138: =IF(K138="Approved",J138,"")
A140: Workflow: (1) enter both neighbor rates, set Survey Locked to Y once confirmed — treat that row's neighbor rate cells as historical from that point and do not edit them again this cycle; a fresh survey next year gets new rows, not overwritten ones. (2) Proposed Rate defaults to the Recommended average; overwrite it directly to set this farm's own figure — that replaces the link with a plain value, same convention used on the Annual Election bundle tick. (3) Set Status to 'Approved' only once the mandated approver for this farm's owning company has actually signed off — Approver Name and Approval Date are that record. (4) Approved Rate is blank until Status = Approved; the Labor Rate Card reads only this column, never Proposed Rate directly, so nothing reaches the live rate card without approval. Valid Until is one year from Approval Date; a rate can still be revised for an individual activity mid-year if a real change is decided — that revision gets its own new row, not an edit to this one, so the history stays intact.

Sheet Labor Rate Card
A1: Activity ID | B1: Activity Name | C1: Unit | D1: Labor Norm (manday / unit) | E1: Wage Rate (ETB / manday) | F1: Computed Cost / Unit (norm x wage) | G1: Final Labor Cost / Unit (ETB) | H1: Status / Source
A2: ='Activity List'!A2 -> T1-001 | B2: ='Activity List'!D2 -> Land Clearing | C2: ='Activity List'!E2 -> ha | F2: =IF(OR(D2="",E2=""),0,D2*E2) -> 0 | G2: =IF('Benchmark Rate Survey'!O5<>"",'Benchmark Rate Survey'!O5,F2) -> 0 | H2: TBD — norm/wage not yet entered; or awaiting Benchmark Rate Survey approval
A3: ='Activity List'!A3 -> T1-002 | B3: ='Activity List'!D3 -> Tree Felling | C3: ='Activity List'!E3 -> ha | F3: =IF(OR(D3="",E3=""),0,D3*E3) -> 0 | G3: =IF('Benchmark Rate Survey'!O6<>"",'Benchmark Rate Survey'!O6,F3) -> 0 | H3: TBD — norm/wage not yet entered; or awaiting Benchmark Rate Survey approval
A4: ='Activity List'!A4 -> T1-003 | B4: ='Activity List'!D4 -> Soil Heaping | C4: ='Activity List'!E4 -> m3 | F4: =IF(OR(D4="",E4=""),0,D4*E4) -> 0 | G4: =IF('Benchmark Rate Survey'!O7<>"",'Benchmark Rate Survey'!O7,F4) -> 0 | H4: TBD — norm/wage not yet entered; or awaiting Benchmark Rate Survey approval
A5: ='Activity List'!A5 -> T1-004 | B5: ='Activity List'!D5 -> Polytube Cutting | C5: ='Activity List'!E5 -> kg | F5: =IF(OR(D5="",E5=""),0,D5*E5) -> 0 | G5: =IF('Benchmark Rate Survey'!O8<>"",'Benchmark Rate Survey'!O8,F5) -> 0 | H5: TBD — norm/wage not yet entered; or awaiting Benchmark Rate Survey approval
A6: ='Activity List'!A6 -> T1-005 | B6: ='Activity List'!D6 -> Polytube Filling | C6: ='Activity List'!E6 -> seedling | F6: =IF(OR(D6="",E6=""),0,D6*E6) -> 0 | G6: =IF('Benchmark Rate Survey'!O9<>"",'Benchmark Rate Survey'!O9,F6) -> 0 | H6: TBD — norm/wage not yet entered; or awaiting Benchmark Rate Survey approval
A7: ='Activity List'!A7 -> T1-006 | B7: ='Activity List'!D7 -> Seedbed Preparation | C7: ='Activity List'!E7 -> bed | F7: =IF(OR(D7="",E7=""),0,D7*E7) -> 0 | G7: =IF('Benchmark Rate Survey'!O10<>"",'Benchmark Rate Survey'!O10,F7) -> 0 | H7: TBD — norm/wage not yet entered; or awaiting Benchmark Rate Survey approval
A8: ='Activity List'!A8 -> T1-007 | B8: ='Activity List'!D8 -> Polytube Arranging | C8: ='Activity List'!E8 -> bed | F8: =IF(OR(D8="",E8=""),0,D8*E8) -> 0 | G8: =IF('Benchmark Rate Survey'!O11<>"",'Benchmark Rate Survey'!O11,F8) -> 0 | H8: TBD — norm/wage not yet entered; or awaiting Benchmark Rate Survey approval
A9: ='Activity List'!A9 -> T1-008 | B9: ='Activity List'!D9 -> Seed Sowing | C9: ='Activity List'!E9 -> bed | F9: =IF(OR(D9="",E9=""),0,D9*E9) -> 0 | G9: =IF('Benchmark Rate Survey'!O12<>"",'Benchmark Rate Survey'!O12,F9) -> 0 | H9: TBD — norm/wage not yet entered; or awaiting Benchmark Rate Survey approval
A10: ='Activity List'!A10 -> T1-009 | B10: ='Activity List'!D10 -> Mulch Material Preparation | C10: ='Activity List'!E10 -> bed | F10: =IF(OR(D10="",E10=""),0,D10*E10) -> 0 | G10: =IF('Benchmark Rate Survey'!O13<>"",'Benchmark Rate Survey'!O13,F10) -> 0 | H10: TBD — norm/wage not yet entered; or awaiting Benchmark Rate Survey approval
A11: ='Activity List'!A11 -> T1-010 | B11: ='Activity List'!D11 -> Mulch Application | C11: ='Activity List'!E11 -> bed | F11: =IF(OR(D11="",E11=""),0,D11*E11) -> 0 | G11: =IF('Benchmark Rate Survey'!O14<>"",'Benchmark Rate Survey'!O14,F11) -> 0 | H11: TBD — norm/wage not yet entered; or awaiting Benchmark Rate Survey approval
A12: ='Activity List'!A12 -> T1-011 | B12: ='Activity List'!D12 -> Shade Material Preparation | C12: ='Activity List'!E12 -> bed | F12: =IF(OR(D12="",E12=""),0,D12*E12) -> 0 | G12: =IF('Benchmark Rate Survey'!O15<>"",'Benchmark Rate Survey'!O15,F12) -> 0 | H12: TBD — norm/wage not yet entered; or awaiting Benchmark Rate Survey approval
A13: ='Activity List'!A13 -> T1-012 | B13: ='Activity List'!D13 -> Shade Construction | C13: ='Activity List'!E13 -> bed | F13: =IF(OR(D13="",E13=""),0,D13*E13) -> 0 | G13: =IF('Benchmark Rate Survey'!O16<>"",'Benchmark Rate Survey'!O16,F13) -> 0 | H13: TBD — norm/wage not yet entered; or awaiting Benchmark Rate Survey approval
... A135: ='Activity List'!A135 -> T3-035 | B135: ='Activity List'!D135 -> Buyer Hosting at SpiralLabs | C135: ='Activity List'!E135 -> event | F135: =IF(OR(D135="",E135=""),0,D135*E135) -> 0 | G135: =IF('Benchmark Rate Survey'!O138<>"",'Benchmark Rate Survey'!O138,F135) -> 0 | H135: TBD — norm/wage not yet entered; or awaiting Benchmark Rate Survey approval
A137: Final Labor Cost/Unit is what every downstream sheet reads. It takes the Benchmark Rate Survey's Approved Rate when one exists for that activity; otherwise it falls back to the norm x wage figure entered directly here. Columns D and E are for activities costed the traditional way (mandays x wage), independent of benchmarking — use whichever route applies to a given activity.

Sheet Material Rate Card
A1: Material ID | B1: Material Name | C1: Unit | D1: Rate (ETB / unit) | E1: Status / Source
E2: Add one row per material input
E3: Add one row per material input
E4: Add one row per material input
E5: Add one row per material input
E6: Add one row per material input
E7: Add one row per material input
E8: Add one row per material input
E9: Add one row per material input
E10: Add one row per material input
E11: Add one row per material input

Sheet Outsourced Services Rate Card
A1: Service ID | B1: Service Name | C1: Unit | D1: Indicative Rate (ETB / unit) | E1: Status / Source
E2: Add one row per outsourced service
E3: Add one row per outsourced service
E4: Add one row per outsourced service
E5: Add one row per outsourced service
E6: Add one row per outsourced service
E7: Add one row per outsourced service
E8: Add one row per outsourced service
E9: Add one row per outsourced service
E10: Add one row per outsourced service
E11: Add one row per outsourced service

Sheet Fee Schedule
B1: Fee Schedule — 3-Year Vision (36 Months)
B2: What the farm owner pays for management, separate from the farm's own operating costs (labor, materials, services) tracked elsewhere in this workbook. Confirmed lines are guaranteed annual fees; Elective lines activate only from the month entered, per the standing election for that tier.
B4: CONFIRMED FEE LINES (annual, guaranteed)
B5: Core Services (Tier 1), Annual Fee
B7: ELECTIVE FEE LINES (annual if fully elected; activates from month entered)
B8: Elective Line | C8: Annual Fee | D8: Activation Month (1-36)
B9: Tier 2 — A. Annual Harvest Management
B10: Tier 2 — B. Coffee Operations
B11: Tier 2 — C. Export and Commercial Operations
B12: Tier 2 — D. Asset Development
B13: Tier 3 — A. Institutional and Strategic Interventions
B14: Tier 3 — B. Technical and Laboratory Services
B16: MONTHLY SCHEDULE
B17: Month # | C17: Month | D17: A. Annual Harvest Mana | E17: B. Coffee Operations | F17: C. Export and Commerci | G17: D. Asset Development | H17: A. Institutional and S | I17: B. Technical and Labor | J17: Confirmed | K17: Elective Subtotal | L17: Total Monthly Fee | M17: Cumulative Total
B18: 1 | C18: =EDATE(Master!$B$3,0) -> 0 | D18: =IF(OR($D$9="",B18<$D$9),0,$C$9/12) -> 0 | E18: =IF(OR($D$10="",B18<$D$10),0,$C$10/12) -> 0 | F18: =IF(OR($D$11="",B18<$D$11),0,$C$11/12) -> 0 | G18: =IF(OR($D$12="",B18<$D$12),0,$C$12/12) -> 0 | H18: =IF(OR($D$13="",B18<$D$13),0,$C$13/12) -> 0 | I18: =IF(OR($D$14="",B18<$D$14),0,$C$14/12) -> 0 | J18: =IF($C$5="",0,$C$5/12) -> 0 | K18: =SUM(D18:I18) -> 0 | L18: =J18+K18 -> 0 | M18: =L18 -> 0
B19: 2 | C19: =EDATE(Master!$B$3,1) -> 31 | D19: =IF(OR($D$9="",B19<$D$9),0,$C$9/12) -> 0 | E19: =IF(OR($D$10="",B19<$D$10),0,$C$10/12) -> 0 | F19: =IF(OR($D$11="",B19<$D$11),0,$C$11/12) -> 0 | G19: =IF(OR($D$12="",B19<$D$12),0,$C$12/12) -> 0 | H19: =IF(OR($D$13="",B19<$D$13),0,$C$13/12) -> 0 | I19: =IF(OR($D$14="",B19<$D$14),0,$C$14/12) -> 0 | J19: =IF($C$5="",0,$C$5/12) -> 0 | K19: =SUM(D19:I19) -> 0 | L19: =J19+K19 -> 0 | M19: =M18+L19 -> 0
B20: 3 | C20: =EDATE(Master!$B$3,2) -> 60 | D20: =IF(OR($D$9="",B20<$D$9),0,$C$9/12) -> 0 | E20: =IF(OR($D$10="",B20<$D$10),0,$C$10/12) -> 0 | F20: =IF(OR($D$11="",B20<$D$11),0,$C$11/12) -> 0 | G20: =IF(OR($D$12="",B20<$D$12),0,$C$12/12) -> 0 | H20: =IF(OR($D$13="",B20<$D$13),0,$C$13/12) -> 0 | I20: =IF(OR($D$14="",B20<$D$14),0,$C$14/12) -> 0 | J20: =IF($C$5="",0,$C$5/12) -> 0 | K20: =SUM(D20:I20) -> 0 | L20: =J20+K20 -> 0 | M20: =M19+L20 -> 0
B21: 4 | C21: =EDATE(Master!$B$3,3) -> 91 | D21: =IF(OR($D$9="",B21<$D$9),0,$C$9/12) -> 0 | E21: =IF(OR($D$10="",B21<$D$10),0,$C$10/12) -> 0 | F21: =IF(OR($D$11="",B21<$D$11),0,$C$11/12) -> 0 | G21: =IF(OR($D$12="",B21<$D$12),0,$C$12/12) -> 0 | H21: =IF(OR($D$13="",B21<$D$13),0,$C$13/12) -> 0 | I21: =IF(OR($D$14="",B21<$D$14),0,$C$14/12) -> 0 | J21: =IF($C$5="",0,$C$5/12) -> 0 | K21: =SUM(D21:I21) -> 0 | L21: =J21+K21 -> 0 | M21: =M20+L21 -> 0
B22: 5 | C22: =EDATE(Master!$B$3,4) -> 121 | D22: =IF(OR($D$9="",B22<$D$9),0,$C$9/12) -> 0 | E22: =IF(OR($D$10="",B22<$D$10),0,$C$10/12) -> 0 | F22: =IF(OR($D$11="",B22<$D$11),0,$C$11/12) -> 0 | G22: =IF(OR($D$12="",B22<$D$12),0,$C$12/12) -> 0 | H22: =IF(OR($D$13="",B22<$D$13),0,$C$13/12) -> 0 | I22: =IF(OR($D$14="",B22<$D$14),0,$C$14/12) -> 0 | J22: =IF($C$5="",0,$C$5/12) -> 0 | K22: =SUM(D22:I22) -> 0 | L22: =J22+K22 -> 0 | M22: =M21+L22 -> 0
B23: 6 | C23: =EDATE(Master!$B$3,5) -> 152 | D23: =IF(OR($D$9="",B23<$D$9),0,$C$9/12) -> 0 | E23: =IF(OR($D$10="",B23<$D$10),0,$C$10/12) -> 0 | F23: =IF(OR($D$11="",B23<$D$11),0,$C$11/12) -> 0 | G23: =IF(OR($D$12="",B23<$D$12),0,$C$12/12) -> 0 | H23: =IF(OR($D$13="",B23<$D$13),0,$C$13/12) -> 0 | I23: =IF(OR($D$14="",B23<$D$14),0,$C$14/12) -> 0 | J23: =IF($C$5="",0,$C$5/12) -> 0 | K23: =SUM(D23:I23) -> 0 | L23: =J23+K23 -> 0 | M23: =M22+L23 -> 0
B24: 7 | C24: =EDATE(Master!$B$3,6) -> 182 | D24: =IF(OR($D$9="",B24<$D$9),0,$C$9/12) -> 0 | E24: =IF(OR($D$10="",B24<$D$10),0,$C$10/12) -> 0 | F24: =IF(OR($D$11="",B24<$D$11),0,$C$11/12) -> 0 | G24: =IF(OR($D$12="",B24<$D$12),0,$C$12/12) -> 0 | H24: =IF(OR($D$13="",B24<$D$13),0,$C$13/12) -> 0 | I24: =IF(OR($D$14="",B24<$D$14),0,$C$14/12) -> 0 | J24: =IF($C$5="",0,$C$5/12) -> 0 | K24: =SUM(D24:I24) -> 0 | L24: =J24+K24 -> 0 | M24: =M23+L24 -> 0
B25: 8 | C25: =EDATE(Master!$B$3,7) -> 213 | D25: =IF(OR($D$9="",B25<$D$9),0,$C$9/12) -> 0 | E25: =IF(OR($D$10="",B25<$D$10),0,$C$10/12) -> 0 | F25: =IF(OR($D$11="",B25<$D$11),0,$C$11/12) -> 0 | G25: =IF(OR($D$12="",B25<$D$12),0,$C$12/12) -> 0 | H25: =IF(OR($D$13="",B25<$D$13),0,$C$13/12) -> 0 | I25: =IF(OR($D$14="",B25<$D$14),0,$C$14/12) -> 0 | J25: =IF($C$5="",0,$C$5/12) -> 0 | K25: =SUM(D25:I25) -> 0 | L25: =J25+K25 -> 0 | M25: =M24+L25 -> 0
B26: 9 | C26: =EDATE(Master!$B$3,8) -> 244 | D26: =IF(OR($D$9="",B26<$D$9),0,$C$9/12) -> 0 | E26: =IF(OR($D$10="",B26<$D$10),0,$C$10/12) -> 0 | F26: =IF(OR($D$11="",B26<$D$11),0,$C$11/12) -> 0 | G26: =IF(OR($D$12="",B26<$D$12),0,$C$12/12) -> 0 | H26: =IF(OR($D$13="",B26<$D$13),0,$C$13/12) -> 0 | I26: =IF(OR($D$14="",B26<$D$14),0,$C$14/12) -> 0 | J26: =IF($C$5="",0,$C$5/12) -> 0 | K26: =SUM(D26:I26) -> 0 | L26: =J26+K26 -> 0 | M26: =M25+L26 -> 0
B27: 10 | C27: =EDATE(Master!$B$3,9) -> 274 | D27: =IF(OR($D$9="",B27<$D$9),0,$C$9/12) -> 0 | E27: =IF(OR($D$10="",B27<$D$10),0,$C$10/12) -> 0 | F27: =IF(OR($D$11="",B27<$D$11),0,$C$11/12) -> 0 | G27: =IF(OR($D$12="",B27<$D$12),0,$C$12/12) -> 0 | H27: =IF(OR($D$13="",B27<$D$13),0,$C$13/12) -> 0 | I27: =IF(OR($D$14="",B27<$D$14),0,$C$14/12) -> 0 | J27: =IF($C$5="",0,$C$5/12) -> 0 | K27: =SUM(D27:I27) -> 0 | L27: =J27+K27 -> 0 | M27: =M26+L27 -> 0
B28: 11 | C28: =EDATE(Master!$B$3,10) -> 305 | D28: =IF(OR($D$9="",B28<$D$9),0,$C$9/12) -> 0 | E28: =IF(OR($D$10="",B28<$D$10),0,$C$10/12) -> 0 | F28: =IF(OR($D$11="",B28<$D$11),0,$C$11/12) -> 0 | G28: =IF(OR($D$12="",B28<$D$12),0,$C$12/12) -> 0 | H28: =IF(OR($D$13="",B28<$D$13),0,$C$13/12) -> 0 | I28: =IF(OR($D$14="",B28<$D$14),0,$C$14/12) -> 0 | J28: =IF($C$5="",0,$C$5/12) -> 0 | K28: =SUM(D28:I28) -> 0 | L28: =J28+K28 -> 0 | M28: =M27+L28 -> 0
B29: 12 | C29: =EDATE(Master!$B$3,11) -> 335 | D29: =IF(OR($D$9="",B29<$D$9),0,$C$9/12) -> 0 | E29: =IF(OR($D$10="",B29<$D$10),0,$C$10/12) -> 0 | F29: =IF(OR($D$11="",B29<$D$11),0,$C$11/12) -> 0 | G29: =IF(OR($D$12="",B29<$D$12),0,$C$12/12) -> 0 | H29: =IF(OR($D$13="",B29<$D$13),0,$C$13/12) -> 0 | I29: =IF(OR($D$14="",B29<$D$14),0,$C$14/12) -> 0 | J29: =IF($C$5="",0,$C$5/12) -> 0 | K29: =SUM(D29:I29) -> 0 | L29: =J29+K29 -> 0 | M29: =M28+L29 -> 0
B30: 13 | C30: =EDATE(Master!$B$3,12) -> 366 | D30: =IF(OR($D$9="",B30<$D$9),0,$C$9/12) -> 0 | E30: =IF(OR($D$10="",B30<$D$10),0,$C$10/12) -> 0 | F30: =IF(OR($D$11="",B30<$D$11),0,$C$11/12) -> 0 | G30: =IF(OR($D$12="",B30<$D$12),0,$C$12/12) -> 0 | H30: =IF(OR($D$13="",B30<$D$13),0,$C$13/12) -> 0 | I30: =IF(OR($D$14="",B30<$D$14),0,$C$14/12) -> 0 | J30: =IF($C$5="",0,$C$5/12) -> 0 | K30: =SUM(D30:I30) -> 0 | L30: =J30+K30 -> 0 | M30: =M29+L30 -> 0
B31: 14 | C31: =EDATE(Master!$B$3,13) -> 397 | D31: =IF(OR($D$9="",B31<$D$9),0,$C$9/12) -> 0 | E31: =IF(OR($D$10="",B31<$D$10),0,$C$10/12) -> 0 | F31: =IF(OR($D$11="",B31<$D$11),0,$C$11/12) -> 0 | G31: =IF(OR($D$12="",B31<$D$12),0,$C$12/12) -> 0 | H31: =IF(OR($D$13="",B31<$D$13),0,$C$13/12) -> 0 | I31: =IF(OR($D$14="",B31<$D$14),0,$C$14/12) -> 0 | J31: =IF($C$5="",0,$C$5/12) -> 0 | K31: =SUM(D31:I31) -> 0 | L31: =J31+K31 -> 0 | M31: =M30+L31 -> 0
B32: 15 | C32: =EDATE(Master!$B$3,14) -> 425 | D32: =IF(OR($D$9="",B32<$D$9),0,$C$9/12) -> 0 | E32: =IF(OR($D$10="",B32<$D$10),0,$C$10/12) -> 0 | F32: =IF(OR($D$11="",B32<$D$11),0,$C$11/12) -> 0 | G32: =IF(OR($D$12="",B32<$D$12),0,$C$12/12) -> 0 | H32: =IF(OR($D$13="",B32<$D$13),0,$C$13/12) -> 0 | I32: =IF(OR($D$14="",B32<$D$14),0,$C$14/12) -> 0 | J32: =IF($C$5="",0,$C$5/12) -> 0 | K32: =SUM(D32:I32) -> 0 | L32: =J32+K32 -> 0 | M32: =M31+L32 -> 0
B33: 16 | C33: =EDATE(Master!$B$3,15) -> 456 | D33: =IF(OR($D$9="",B33<$D$9),0,$C$9/12) -> 0 | E33: =IF(OR($D$10="",B33<$D$10),0,$C$10/12) -> 0 | F33: =IF(OR($D$11="",B33<$D$11),0,$C$11/12) -> 0 | G33: =IF(OR($D$12="",B33<$D$12),0,$C$12/12) -> 0 | H33: =IF(OR($D$13="",B33<$D$13),0,$C$13/12) -> 0 | I33: =IF(OR($D$14="",B33<$D$14),0,$C$14/12) -> 0 | J33: =IF($C$5="",0,$C$5/12) -> 0 | K33: =SUM(D33:I33) -> 0 | L33: =J33+K33 -> 0 | M33: =M32+L33 -> 0
B34: 17 | C34: =EDATE(Master!$B$3,16) -> 486 | D34: =IF(OR($D$9="",B34<$D$9),0,$C$9/12) -> 0 | E34: =IF(OR($D$10="",B34<$D$10),0,$C$10/12) -> 0 | F34: =IF(OR($D$11="",B34<$D$11),0,$C$11/12) -> 0 | G34: =IF(OR($D$12="",B34<$D$12),0,$C$12/12) -> 0 | H34: =IF(OR($D$13="",B34<$D$13),0,$C$13/12) -> 0 | I34: =IF(OR($D$14="",B34<$D$14),0,$C$14/12) -> 0 | J34: =IF($C$5="",0,$C$5/12) -> 0 | K34: =SUM(D34:I34) -> 0 | L34: =J34+K34 -> 0 | M34: =M33+L34 -> 0
B35: 18 | C35: =EDATE(Master!$B$3,17) -> 517 | D35: =IF(OR($D$9="",B35<$D$9),0,$C$9/12) -> 0 | E35: =IF(OR($D$10="",B35<$D$10),0,$C$10/12) -> 0 | F35: =IF(OR($D$11="",B35<$D$11),0,$C$11/12) -> 0 | G35: =IF(OR($D$12="",B35<$D$12),0,$C$12/12) -> 0 | H35: =IF(OR($D$13="",B35<$D$13),0,$C$13/12) -> 0 | I35: =IF(OR($D$14="",B35<$D$14),0,$C$14/12) -> 0 | J35: =IF($C$5="",0,$C$5/12) -> 0 | K35: =SUM(D35:I35) -> 0 | L35: =J35+K35 -> 0 | M35: =M34+L35 -> 0
B36: 19 | C36: =EDATE(Master!$B$3,18) -> 547 | D36: =IF(OR($D$9="",B36<$D$9),0,$C$9/12) -> 0 | E36: =IF(OR($D$10="",B36<$D$10),0,$C$10/12) -> 0 | F36: =IF(OR($D$11="",B36<$D$11),0,$C$11/12) -> 0 | G36: =IF(OR($D$12="",B36<$D$12),0,$C$12/12) -> 0 | H36: =IF(OR($D$13="",B36<$D$13),0,$C$13/12) -> 0 | I36: =IF(OR($D$14="",B36<$D$14),0,$C$14/12) -> 0 | J36: =IF($C$5="",0,$C$5/12) -> 0 | K36: =SUM(D36:I36) -> 0 | L36: =J36+K36 -> 0 | M36: =M35+L36 -> 0
B37: 20 | C37: =EDATE(Master!$B$3,19) -> 578 | D37: =IF(OR($D$9="",B37<$D$9),0,$C$9/12) -> 0 | E37: =IF(OR($D$10="",B37<$D$10),0,$C$10/12) -> 0 | F37: =IF(OR($D$11="",B37<$D$11),0,$C$11/12) -> 0 | G37: =IF(OR($D$12="",B37<$D$12),0,$C$12/12) -> 0 | H37: =IF(OR($D$13="",B37<$D$13),0,$C$13/12) -> 0 | I37: =IF(OR($D$14="",B37<$D$14),0,$C$14/12) -> 0 | J37: =IF($C$5="",0,$C$5/12) -> 0 | K37: =SUM(D37:I37) -> 0 | L37: =J37+K37 -> 0 | M37: =M36+L37 -> 0
B38: 21 | C38: =EDATE(Master!$B$3,20) -> 609 | D38: =IF(OR($D$9="",B38<$D$9),0,$C$9/12) -> 0 | E38: =IF(OR($D$10="",B38<$D$10),0,$C$10/12) -> 0 | F38: =IF(OR($D$11="",B38<$D$11),0,$C$11/12) -> 0 | G38: =IF(OR($D$12="",B38<$D$12),0,$C$12/12) -> 0 | H38: =IF(OR($D$13="",B38<$D$13),0,$C$13/12) -> 0 | I38: =IF(OR($D$14="",B38<$D$14),0,$C$14/12) -> 0 | J38: =IF($C$5="",0,$C$5/12) -> 0 | K38: =SUM(D38:I38) -> 0 | L38: =J38+K38 -> 0 | M38: =M37+L38 -> 0
B39: 22 | C39: =EDATE(Master!$B$3,21) -> 639 | D39: =IF(OR($D$9="",B39<$D$9),0,$C$9/12) -> 0 | E39: =IF(OR($D$10="",B39<$D$10),0,$C$10/12) -> 0 | F39: =IF(OR($D$11="",B39<$D$11),0,$C$11/12) -> 0 | G39: =IF(OR($D$12="",B39<$D$12),0,$C$12/12) -> 0 | H39: =IF(OR($D$13="",B39<$D$13),0,$C$13/12) -> 0 | I39: =IF(OR($D$14="",B39<$D$14),0,$C$14/12) -> 0 | J39: =IF($C$5="",0,$C$5/12) -> 0 | K39: =SUM(D39:I39) -> 0 | L39: =J39+K39 -> 0 | M39: =M38+L39 -> 0
B40: 23 | C40: =EDATE(Master!$B$3,22) -> 670 | D40: =IF(OR($D$9="",B40<$D$9),0,$C$9/12) -> 0 | E40: =IF(OR($D$10="",B40<$D$10),0,$C$10/12) -> 0 | F40: =IF(OR($D$11="",B40<$D$11),0,$C$11/12) -> 0 | G40: =IF(OR($D$12="",B40<$D$12),0,$C$12/12) -> 0 | H40: =IF(OR($D$13="",B40<$D$13),0,$C$13/12) -> 0 | I40: =IF(OR($D$14="",B40<$D$14),0,$C$14/12) -> 0 | J40: =IF($C$5="",0,$C$5/12) -> 0 | K40: =SUM(D40:I40) -> 0 | L40: =J40+K40 -> 0 | M40: =M39+L40 -> 0
B41: 24 | C41: =EDATE(Master!$B$3,23) -> 700 | D41: =IF(OR($D$9="",B41<$D$9),0,$C$9/12) -> 0 | E41: =IF(OR($D$10="",B41<$D$10),0,$C$10/12) -> 0 | F41: =IF(OR($D$11="",B41<$D$11),0,$C$11/12) -> 0 | G41: =IF(OR($D$12="",B41<$D$12),0,$C$12/12) -> 0 | H41: =IF(OR($D$13="",B41<$D$13),0,$C$13/12) -> 0 | I41: =IF(OR($D$14="",B41<$D$14),0,$C$14/12) -> 0 | J41: =IF($C$5="",0,$C$5/12) -> 0 | K41: =SUM(D41:I41) -> 0 | L41: =J41+K41 -> 0 | M41: =M40+L41 -> 0
B42: 25 | C42: =EDATE(Master!$B$3,24) -> 731 | D42: =IF(OR($D$9="",B42<$D$9),0,$C$9/12) -> 0 | E42: =IF(OR($D$10="",B42<$D$10),0,$C$10/12) -> 0 | F42: =IF(OR($D$11="",B42<$D$11),0,$C$11/12) -> 0 | G42: =IF(OR($D$12="",B42<$D$12),0,$C$12/12) -> 0 | H42: =IF(OR($D$13="",B42<$D$13),0,$C$13/12) -> 0 | I42: =IF(OR($D$14="",B42<$D$14),0,$C$14/12) -> 0 | J42: =IF($C$5="",0,$C$5/12) -> 0 | K42: =SUM(D42:I42) -> 0 | L42: =J42+K42 -> 0 | M42: =M41+L42 -> 0
B43: 26 | C43: =EDATE(Master!$B$3,25) -> 762 | D43: =IF(OR($D$9="",B43<$D$9),0,$C$9/12) -> 0 | E43: =IF(OR($D$10="",B43<$D$10),0,$C$10/12) -> 0 | F43: =IF(OR($D$11="",B43<$D$11),0,$C$11/12) -> 0 | G43: =IF(OR($D$12="",B43<$D$12),0,$C$12/12) -> 0 | H43: =IF(OR($D$13="",B43<$D$13),0,$C$13/12) -> 0 | I43: =IF(OR($D$14="",B43<$D$14),0,$C$14/12) -> 0 | J43: =IF($C$5="",0,$C$5/12) -> 0 | K43: =SUM(D43:I43) -> 0 | L43: =J43+K43 -> 0 | M43: =M42+L43 -> 0
...

Sheet Annual Election
A1: Annual Election — Year 1
A2: Core Bundle Tick (Y elects every Tier 1 activity at once):
A3: Tier 1 (Core): tick the bundle above to elect all at once, or overwrite an individual row's Elected cell directly to remove or add it one by one. Tier 2 (Projects) and Tier 3 (Interventions) have no bundle and no default — every row is elected individually, only once the commercial agreement for that work has been settled outside the platform.
A4: Block ID | B4: Activity ID | C4: Category | D4: Activity Name | E4: Default Window Start | F4: Default Window End | G4: Planned Duration (days) | H4: Effective End Date (auto) | I4: Elected (Y/N)
A5: =Master!A$6 -> 0 | B5: ='Activity List'!A2 -> T1-001 | C5: ='Activity List'!C2 -> Nursery | D5: ='Activity List'!D2 -> Land Clearing | E5: =IF(Master!$B$3="","",EDATE(Master!$B$3,0)) | F5: =IF(Master!$B$3="","",EDATE(Master!$B$3,6)-1) | H5: =IF(E5="","",IF(G5="",F5,E5+G5-1)) | I5: ='Annual Election'!$D$2 -> 0
A6: =Master!A$6 -> 0 | B6: ='Activity List'!A3 -> T1-002 | C6: ='Activity List'!C3 -> Nursery | D6: ='Activity List'!D3 -> Tree Felling | E6: =IF(Master!$B$3="","",EDATE(Master!$B$3,0)) | F6: =IF(Master!$B$3="","",EDATE(Master!$B$3,6)-1) | H6: =IF(E6="","",IF(G6="",F6,E6+G6-1)) | I6: ='Annual Election'!$D$2 -> 0
A7: =Master!A$6 -> 0 | B7: ='Activity List'!A4 -> T1-003 | C7: ='Activity List'!C4 -> Nursery | D7: ='Activity List'!D4 -> Soil Heaping | E7: =IF(Master!$B$3="","",EDATE(Master!$B$3,0)) | F7: =IF(Master!$B$3="","",EDATE(Master!$B$3,6)-1) | H7: =IF(E7="","",IF(G7="",F7,E7+G7-1)) | I7: ='Annual Election'!$D$2 -> 0
A8: =Master!A$6 -> 0 | B8: ='Activity List'!A5 -> T1-004 | C8: ='Activity List'!C5 -> Nursery | D8: ='Activity List'!D5 -> Polytube Cutting | E8: =IF(Master!$B$3="","",EDATE(Master!$B$3,0)) | F8: =IF(Master!$B$3="","",EDATE(Master!$B$3,6)-1) | H8: =IF(E8="","",IF(G8="",F8,E8+G8-1)) | I8: ='Annual Election'!$D$2 -> 0
A9: =Master!A$6 -> 0 | B9: ='Activity List'!A6 -> T1-005 | C9: ='Activity List'!C6 -> Nursery | D9: ='Activity List'!D6 -> Polytube Filling | E9: =IF(Master!$B$3="","",EDATE(Master!$B$3,0)) | F9: =IF(Master!$B$3="","",EDATE(Master!$B$3,6)-1) | H9: =IF(E9="","",IF(G9="",F9,E9+G9-1)) | I9: ='Annual Election'!$D$2 -> 0
A10: =Master!A$6 -> 0 | B10: ='Activity List'!A7 -> T1-006 | C10: ='Activity List'!C7 -> Nursery | D10: ='Activity List'!D7 -> Seedbed Preparation | E10: =IF(Master!$B$3="","",EDATE(Master!$B$3,0)) | F10: =IF(Master!$B$3="","",EDATE(Master!$B$3,6)-1) | H10: =IF(E10="","",IF(G10="",F10,E10+G10-1)) | I10: ='Annual Election'!$D$2 -> 0
A11: =Master!A$6 -> 0 | B11: ='Activity List'!A8 -> T1-007 | C11: ='Activity List'!C8 -> Nursery | D11: ='Activity List'!D8 -> Polytube Arranging | E11: =IF(Master!$B$3="","",EDATE(Master!$B$3,0)) | F11: =IF(Master!$B$3="","",EDATE(Master!$B$3,6)-1) | H11: =IF(E11="","",IF(G11="",F11,E11+G11-1)) | I11: ='Annual Election'!$D$2 -> 0
A12: =Master!A$6 -> 0 | B12: ='Activity List'!A9 -> T1-008 | C12: ='Activity List'!C9 -> Nursery | D12: ='Activity List'!D9 -> Seed Sowing | E12: =IF(Master!$B$3="","",EDATE(Master!$B$3,0)) | F12: =IF(Master!$B$3="","",EDATE(Master!$B$3,6)-1) | H12: =IF(E12="","",IF(G12="",F12,E12+G12-1)) | I12: ='Annual Election'!$D$2 -> 0
A13: =Master!A$6 -> 0 | B13: ='Activity List'!A10 -> T1-009 | C13: ='Activity List'!C10 -> Nursery | D13: ='Activity List'!D10 -> Mulch Material Preparation | E13: =IF(Master!$B$3="","",EDATE(Master!$B$3,0)) | F13: =IF(Master!$B$3="","",EDATE(Master!$B$3,6)-1) | H13: =IF(E13="","",IF(G13="",F13,E13+G13-1)) | I13: ='Annual Election'!$D$2 -> 0
A14: =Master!A$6 -> 0 | B14: ='Activity List'!A11 -> T1-010 | C14: ='Activity List'!C11 -> Nursery | D14: ='Activity List'!D11 -> Mulch Application | E14: =IF(Master!$B$3="","",EDATE(Master!$B$3,0)) | F14: =IF(Master!$B$3="","",EDATE(Master!$B$3,6)-1) | H14: =IF(E14="","",IF(G14="",F14,E14+G14-1)) | I14: ='Annual Election'!$D$2 -> 0
A15: =Master!A$6 -> 0 | B15: ='Activity List'!A12 -> T1-011 | C15: ='Activity List'!C12 -> Nursery | D15: ='Activity List'!D12 -> Shade Material Preparation | E15: =IF(Master!$B$3="","",EDATE(Master!$B$3,0)) | F15: =IF(Master!$B$3="","",EDATE(Master!$B$3,6)-1) | H15: =IF(E15="","",IF(G15="",F15,E15+G15-1)) | I15: ='Annual Election'!$D$2 -> 0
A16: =Master!A$6 -> 0 | B16: ='Activity List'!A13 -> T1-012 | C16: ='Activity List'!C13 -> Nursery | D16: ='Activity List'!D13 -> Shade Construction | E16: =IF(Master!$B$3="","",EDATE(Master!$B$3,0)) | F16: =IF(Master!$B$3="","",EDATE(Master!$B$3,6)-1) | H16: =IF(E16="","",IF(G16="",F16,E16+G16-1)) | I16: ='Annual Election'!$D$2 -> 0
... A20: =Master!A$6 -> 0 | B20: ='Activity List'!A17 -> T1-016 | C20: ='Activity List'!C17 -> Nursery | D20: ='Activity List'!D17 -> Shade Removal | E20: =IF(Master!$B$3="","",EDATE(Master!$B$3,0)) | F20: =IF(Master!$B$3="","",EDATE(Master!$B$3,6)-1) | H20: =IF(E20="","",IF(G20="",F20,E20+G20-1)) | I20: ='Annual Election'!$D$2 -> 0
A21: =Master!A$6 -> 0 | B21: ='Activity List'!A18 -> T1-017 | C21: ='Activity List'!C18 -> Young Coffee | D21: ='Activity List'!D18 -> Hoeing (Young Coffee) | E21: =IF(Master!$B$3="","",EDATE(Master!$B$3,0)) | F21: =IF(Master!$B$3="","",EDATE(Master!$B$3,12)-1) | H21: =IF(E21="","",IF(G21="",F21,E21+G21-1)) | I21: ='Annual Election'!$D$2 -> 0
A22: =Master!A$6 -> 0 | B22: ='Activity List'!A19 -> T1-018 | C22: ='Activity List'!C19 -> Young Coffee | D22: ='Activity List'!D19 -> Fertilizing (Young Coffee) | E22: =IF(Master!$B$3="","",EDATE(Master!$B$3,0)) | F22: =IF(Master!$B$3="","",EDATE(Master!$B$3,12)-1) | H22: =IF(E22="","",IF(G22="",F22,E22+G22-1)) | I22: ='Annual Election'!$D$2 -> 0
A23: =Master!A$6 -> 0 | B23: ='Activity List'!A20 -> T1-019 | C23: ='Activity List'!C20 -> Young Coffee | D23: ='Activity List'!D20 -> Ring Weeding of Seedlings | E23: =IF(Master!$B$3="","",EDATE(Master!$B$3,0)) | F23: =IF(Master!$B$3="","",EDATE(Master!$B$3,12)-1) | H23: =IF(E23="","",IF(G23="",F23,E23+G23-1)) | I23: ='Annual Election'!$D$2 -> 0
A24: =Master!A$6 -> 0 | B24: ='Activity List'!A21 -> T1-020 | C24: ='Activity List'!C21 -> Young Coffee | D24: ='Activity List'!D21 -> Shade Tree Regulation | E24: =IF(Master!$B$3="","",EDATE(Master!$B$3,0)) | F24: =IF(Master!$B$3="","",EDATE(Master!$B$3,12)-1) | H24: =IF(E24="","",IF(G24="",F24,E24+G24-1)) | I24: ='Annual Election'!$D$2 -> 0
A25: =Master!A$6 -> 0 | B25: ='Activity List'!A22 -> T1-021 | C25: ='Activity List'!C22 -> Young Coffee | D25: ='Activity List'!D22 -> Compost Preparation | E25: =IF(Master!$B$3="","",EDATE(Master!$B$3,0)) | F25: =IF(Master!$B$3="","",EDATE(Master!$B$3,12)-1) | H25: =IF(E25="","",IF(G25="",F25,E25+G25-1)) | I25: ='Annual Election'!$D$2 -> 0
A26: =Master!A$6 -> 0 | B26: ='Activity List'!A23 -> T1-022 | C26: ='Activity List'!C23 -> Young Coffee | D26: ='Activity List'!D23 -> Ridge Construction | E26: =IF(Master!$B$3="","",EDATE(Master!$B$3,0)) | F26: =IF(Master!$B$3="","",EDATE(Master!$B$3,12)-1) | H26: =IF(E26="","",IF(G26="",F26,E26+G26-1)) | I26: ='Annual Election'!$D$2 -> 0
A27: =Master!A$6 -> 0 | B27: ='Activity List'!A24 -> T1-023 | C27: ='Activity List'!C24 -> Matured Coffee | D27: ='Activity List'!D24 -> Manual Weeding | E27: =IF(Master!$B$3="","",EDATE(Master!$B$3,0)) | F27: =IF(Master!$B$3="","",EDATE(Master!$B$3,12)-1) | H27: =IF(E27="","",IF(G27="",F27,E27+G27-1)) | I27: ='Annual Election'!$D$2 -> 0
A28: =Master!A$6 -> 0 | B28: ='Activity List'!A25 -> T1-024 | C28: ='Activity List'!C25 -> Matured Coffee | D28: ='Activity List'!D25 -> Chemical Weeding | E28: =IF(Master!$B$3="","",EDATE(Master!$B$3,0)) | F28: =IF(Master!$B$3="","",EDATE(Master!$B$3,12)-1) | H28: =IF(E28="","",IF(G28="",F28,E28+G28-1)) | I28: ='Annual Election'!$D$2 -> 0
A29: =Master!A$6 -> 0 | B29: ='Activity List'!A26 -> T1-025 | C29: ='Activity List'!C26 -> Matured Coffee | D29: ='Activity List'!D26 -> Pruning (Matured Coffee) | E29: =IF(Master!$B$3="","",EDATE(Master!$B$3,0)) | F29: =IF(Master!$B$3="","",EDATE(Master!$B$3,12)-1) | H29: =IF(E29="","",IF(G29="",F29,E29+G29-1)) | I29: ='Annual Election'!$D$2 -> 0
A30: =Master!A$6 -> 0 | B30: ='Activity List'!A27 -> T1-026 | C30: ='Activity List'!C27 -> Matured Coffee | D30: ='Activity List'!D27 -> Topping (Matured Coffee) | E30: =IF(Master!$B$3="","",EDATE(Master!$B$3,0)) | F30: =IF(Master!$B$3="","",EDATE(Master!$B$3,12)-1) | H30: =IF(E30="","",IF(G30="",F30,E30+G30-1)) | I30: ='Annual Election'!$D$2 -> 0
A31: =Master!A$6 -> 0 | B31: ='Activity List'!A28 -> T1-027 | C31: ='Activity List'!C28 -> Matured Coffee | D31: ='Activity List'!D28 -> Handling and Desuckering | E31: =IF(Master!$B$3="","",EDATE(Master!$B$3,0)) | F31: =IF(Master!$B$3="","",EDATE(Master!$B$3,12)-1) | H31: =IF(E31="","",IF(G31="",F31,E31+G31-1)) | I31: ='Annual Election'!$D$2 -> 0
A32: =Master!A$6 -> 0 | B32: ='Activity List'!A29 -> T1-028 | C32: ='Activity List'!C29 -> Matured Coffee | D32: ='Activity List'!D29 -> Coffee Tree Support/Staking | E32: =IF(Master!$B$3="","",EDATE(Master!$B$3,0)) | F32: =IF(Master!$B$3="","",EDATE(Master!$B$3,12)-1) | H32: =IF(E32="","",IF(G32="",F32,E32+G32-1)) | I32: ='Annual Election'!$D$2 -> 0
A33: =Master!A$6 -> 0 | B33: ='Activity List'!A30 -> T1-029 | C33: ='Activity List'!C30 -> Matured Coffee | D33: ='Activity List'!D30 -> Watchman Tower (Matured Block) | E33: =IF(Master!$B$3="","",EDATE(Master!$B$3,0)) | F33: =IF(Master!$B$3="","",EDATE(Master!$B$3,12)-1) | H33: =IF(E33="","",IF(G33="",F33,E33+G33-1)) | I33: ='Annual Election'!$D$2 -> 0
A34: =Master!A$6 -> 0 | B34: ='Activity List'!A31 -> T1-030 | C34: ='Activity List'!C31 -> Infilling | D34: ='Activity List'!D31 -> Infill Peg Preparation | E34: =IF(Master!$B$3="","",EDATE(Master!$B$3,8)) | F34: =IF(Master!$B$3="","",EDATE(Master!$B$3,11)-1) | H34: =IF(E34="","",IF(G34="",F34,E34+G34-1)) | I34: ='Annual Election'!$D$2 -> 0
A35: =Master!A$6 -> 0 | B35: ='Activity List'!A32 -> T1-031 | C35: ='Activity List'!C32 -> Infilling | D35: ='Activity List'!D32 -> Infill Layout and Pegging | E35: =IF(Master!$B$3="","",EDATE(Master!$B$3,8)) | F35: =IF(Master!$B$3="","",EDATE(Master!$B$3,11)-1) | H35: =IF(E35="","",IF(G35="",F35,E35+G35-1)) | I35: ='Annual Election'!$D$2 -> 0
A36: =Master!A$6 -> 0 | B36: ='Activity List'!A33 -> T1-032 | C36: ='Activity List'!C33 -> Infilling | D36: ='Activity List'!D33 -> Infill Hole Digging | E36: =IF(Master!$B$3="","",EDATE(Master!$B$3,8)) | F36: =IF(Master!$B$3="","",EDATE(Master!$B$3,11)-1) | H36: =IF(E36="","",IF(G36="",F36,E36+G36-1)) | I36: ='Annual Election'!$D$2 -> 0
A37: =Master!A$6 -> 0 | B37: ='Activity List'!A34 -> T1-033 | C37: ='Activity List'!C34 -> Infilling | D37: ='Activity List'!D34 -> Infill Hole Refilling | E37: =IF(Master!$B$3="","",EDATE(Master!$B$3,8)) | F37: =IF(Master!$B$3="","",EDATE(Master!$B$3,11)-1) | H37: =IF(E37="","",IF(G37="",F37,E37+G37-1)) | I37: ='Annual Election'!$D$2 -> 0
A38: =Master!A$6 -> 0 | B38: ='Activity List'!A35 -> T1-034 | C38: ='Activity List'!C35 -> Infilling | D38: ='Activity List'!D35 -> Infill Watchman Tower Prep | E38: =IF(Master!$B$3="","",EDATE(Master!$B$3,8)) | F38: =IF(Master!$B$3="","",EDATE(Master!$B$3,11)-1) | H38: =IF(E38="","",IF(G38="",F38,E38+G38-1)) | I38: ='Annual Election'!$D$2 -> 0
A39: =Master!A$6 -> 0 | B39: ='Activity List'!A36 -> T1-035 | C39: ='Activity List'!C36 -> Infilling | D39: ='Activity List'!D36 -> Infill Seedling Transport | E39: =IF(Master!$B$3="","",EDATE(Master!$B$3,8)) | F39: =IF(Master!$B$3="","",EDATE(Master!$B$3,11)-1) | H39: =IF(E39="","",IF(G39="",F39,E39+G39-1)) | I39: ='Annual Election'!$D$2 -> 0
A40: =Master!A$6 -> 0 | B40: ='Activity List'!A37 -> T1-036 | C40: ='Activity List'!C37 -> Infilling | D40: ='Activity List'!D37 -> Infill Planting | E40: =IF(Master!$B$3="","",EDATE(Master!$B$3,8)) | F40: =IF(Master!$B$3="","",EDATE(Master!$B$3,11)-1) | H40: =IF(E40="","",IF(G40="",F40,E40+G40-1)) | I40: ='Annual Election'!$D$2 -> 0
A41: =Master!A$6 -> 0 | B41: ='Activity List'!A38 -> T1-037 | C41: ='Activity List'!C38 -> Picking & Related | D41: ='Activity List'!D38 -> Harvest Watchman Tower Prep | E41: =IF(Master!$B$3="","",EDATE(Master!$B$3,0)) | F41: =IF(Master!$B$3="","",EDATE(Master!$B$3,7)-1) | H41: =IF(E41="","",IF(G41="",F41,E41+G41-1)) | I41: ='Annual Election'!$D$2 -> 0
A42: =Master!A$6 -> 0 | B42: ='Activity List'!A39 -> T1-038 | C42: ='Activity List'!C39 -> Picking & Related | D42: ='Activity List'!D39 -> Drying Bed Material Prep and Transport | E42: =IF(Master!$B$3="","",EDATE(Master!$B$3,0)) | F42: =IF(Master!$B$3="","",EDATE(Master!$B$3,7)-1) | H42: =IF(E42="","",IF(G42="",F42,E42+G42-1)) | I42: ='Annual Election'!$D$2 -> 0
A43: =Master!A$6 -> 0 | B43: ='Activity List'!A40 -> T1-039 | C43: ='Activity List'!C40 -> Picking & Related | D43: ='Activity List'!D40 -> Drying Bed Site Cleaning | E43: =IF(Master!$B$3="","",EDATE(Master!$B$3,0)) | F43: =IF(Master!$B$3="","",EDATE(Master!$B$3,7)-1) | H43: =IF(E43="","",IF(G43="",F43,E43+G43-1)) | I43: ='Annual Election'!$D$2 -> 0
...

Sheet Activity Plan
A1: Block ID | B1: Block Name | C1: Activity ID | D1: Activity Name | E1: Tier | F1: Unit | G1: Tick (Y/N) | H1: Planned Qty | I1: Labor Rate / Unit (ETB) | J1: Planned Labor Cost (ETB) | K1: Window Start (helper) | L1: Window End (helper) | M1: Weeks Spanned (helper) | N1: Weekly Allocation (ETB, helper)
A2: =Master!A$6 -> 0 | B2: =Master!B$6 -> 0 | C2: ='Activity List'!A2 -> T1-001 | D2: ='Activity List'!D2 -> Land Clearing | E2: ='Activity List'!B2 -> Tier 1 — Core Services | F2: ='Activity List'!E2 -> ha | G2: ='Annual Election'!I5 -> 0 | I2: =IFERROR(INDEX('Labor Rate Card'!$G$2:$G$135,MATCH(C2,'Labor Rate Card'!$A$2:$A$135,0)),0) -> 0 | J2: =IF(G2="Y",H2*I2,0) -> 0 | K2: ='Annual Election'!E5 | L2: ='Annual Election'!H5 | M2: =IF(OR(K2="",L2=""),"",ROUNDUP((L2-K2+1)/7,0)) | N2: =IF(OR(J2="",M2="",M2=0),0,J2/M2) -> 0
A3: =Master!A$6 -> 0 | B3: =Master!B$6 -> 0 | C3: ='Activity List'!A3 -> T1-002 | D3: ='Activity List'!D3 -> Tree Felling | E3: ='Activity List'!B3 -> Tier 1 — Core Services | F3: ='Activity List'!E3 -> ha | G3: ='Annual Election'!I6 -> 0 | I3: =IFERROR(INDEX('Labor Rate Card'!$G$2:$G$135,MATCH(C3,'Labor Rate Card'!$A$2:$A$135,0)),0) -> 0 | J3: =IF(G3="Y",H3*I3,0) -> 0 | K3: ='Annual Election'!E6 | L3: ='Annual Election'!H6 | M3: =IF(OR(K3="",L3=""),"",ROUNDUP((L3-K3+1)/7,0)) | N3: =IF(OR(J3="",M3="",M3=0),0,J3/M3) -> 0
A4: =Master!A$6 -> 0 | B4: =Master!B$6 -> 0 | C4: ='Activity List'!A4 -> T1-003 | D4: ='Activity List'!D4 -> Soil Heaping | E4: ='Activity List'!B4 -> Tier 1 — Core Services | F4: ='Activity List'!E4 -> m3 | G4: ='Annual Election'!I7 -> 0 | I4: =IFERROR(INDEX('Labor Rate Card'!$G$2:$G$135,MATCH(C4,'Labor Rate Card'!$A$2:$A$135,0)),0) -> 0 | J4: =IF(G4="Y",H4*I4,0) -> 0 | K4: ='Annual Election'!E7 | L4: ='Annual Election'!H7 | M4: =IF(OR(K4="",L4=""),"",ROUNDUP((L4-K4+1)/7,0)) | N4: =IF(OR(J4="",M4="",M4=0),0,J4/M4) -> 0
A5: =Master!A$6 -> 0 | B5: =Master!B$6 -> 0 | C5: ='Activity List'!A5 -> T1-004 | D5: ='Activity List'!D5 -> Polytube Cutting | E5: ='Activity List'!B5 -> Tier 1 — Core Services | F5: ='Activity List'!E5 -> kg | G5: ='Annual Election'!I8 -> 0 | I5: =IFERROR(INDEX('Labor Rate Card'!$G$2:$G$135,MATCH(C5,'Labor Rate Card'!$A$2:$A$135,0)),0) -> 0 | J5: =IF(G5="Y",H5*I5,0) -> 0 | K5: ='Annual Election'!E8 | L5: ='Annual Election'!H8 | M5: =IF(OR(K5="",L5=""),"",ROUNDUP((L5-K5+1)/7,0)) | N5: =IF(OR(J5="",M5="",M5=0),0,J5/M5) -> 0
A6: =Master!A$6 -> 0 | B6: =Master!B$6 -> 0 | C6: ='Activity List'!A6 -> T1-005 | D6: ='Activity List'!D6 -> Polytube Filling | E6: ='Activity List'!B6 -> Tier 1 — Core Services | F6: ='Activity List'!E6 -> seedling | G6: ='Annual Election'!I9 -> 0 | I6: =IFERROR(INDEX('Labor Rate Card'!$G$2:$G$135,MATCH(C6,'Labor Rate Card'!$A$2:$A$135,0)),0) -> 0 | J6: =IF(G6="Y",H6*I6,0) -> 0 | K6: ='Annual Election'!E9 | L6: ='Annual Election'!H9 | M6: =IF(OR(K6="",L6=""),"",ROUNDUP((L6-K6+1)/7,0)) | N6: =IF(OR(J6="",M6="",M6=0),0,J6/M6) -> 0
A7: =Master!A$6 -> 0 | B7: =Master!B$6 -> 0 | C7: ='Activity List'!A7 -> T1-006 | D7: ='Activity List'!D7 -> Seedbed Preparation | E7: ='Activity List'!B7 -> Tier 1 — Core Services | F7: ='Activity List'!E7 -> bed | G7: ='Annual Election'!I10 -> 0 | I7: =IFERROR(INDEX('Labor Rate Card'!$G$2:$G$135,MATCH(C7,'Labor Rate Card'!$A$2:$A$135,0)),0) -> 0 | J7: =IF(G7="Y",H7*I7,0) -> 0 | K7: ='Annual Election'!E10 | L7: ='Annual Election'!H10 | M7: =IF(OR(K7="",L7=""),"",ROUNDUP((L7-K7+1)/7,0)) | N7: =IF(OR(J7="",M7="",M7=0),0,J7/M7) -> 0
A8: =Master!A$6 -> 0 | B8: =Master!B$6 -> 0 | C8: ='Activity List'!A8 -> T1-007 | D8: ='Activity List'!D8 -> Polytube Arranging | E8: ='Activity List'!B8 -> Tier 1 — Core Services | F8: ='Activity List'!E8 -> bed | G8: ='Annual Election'!I11 -> 0 | I8: =IFERROR(INDEX('Labor Rate Card'!$G$2:$G$135,MATCH(C8,'Labor Rate Card'!$A$2:$A$135,0)),0) -> 0 | J8: =IF(G8="Y",H8*I8,0) -> 0 | K8: ='Annual Election'!E11 | L8: ='Annual Election'!H11 | M8: =IF(OR(K8="",L8=""),"",ROUNDUP((L8-K8+1)/7,0)) | N8: =IF(OR(J8="",M8="",M8=0),0,J8/M8) -> 0
A9: =Master!A$6 -> 0 | B9: =Master!B$6 -> 0 | C9: ='Activity List'!A9 -> T1-008 | D9: ='Activity List'!D9 -> Seed Sowing | E9: ='Activity List'!B9 -> Tier 1 — Core Services | F9: ='Activity List'!E9 -> bed | G9: ='Annual Election'!I12 -> 0 | I9: =IFERROR(INDEX('Labor Rate Card'!$G$2:$G$135,MATCH(C9,'Labor Rate Card'!$A$2:$A$135,0)),0) -> 0 | J9: =IF(G9="Y",H9*I9,0) -> 0 | K9: ='Annual Election'!E12 | L9: ='Annual Election'!H12 | M9: =IF(OR(K9="",L9=""),"",ROUNDUP((L9-K9+1)/7,0)) | N9: =IF(OR(J9="",M9="",M9=0),0,J9/M9) -> 0
A10: =Master!A$6 -> 0 | B10: =Master!B$6 -> 0 | C10: ='Activity List'!A10 -> T1-009 | D10: ='Activity List'!D10 -> Mulch Material Preparation | E10: ='Activity List'!B10 -> Tier 1 — Core Services | F10: ='Activity List'!E10 -> bed | G10: ='Annual Election'!I13 -> 0 | I10: =IFERROR(INDEX('Labor Rate Card'!$G$2:$G$135,MATCH(C10,'Labor Rate Card'!$A$2:$A$135,0)),0) -> 0 | J10: =IF(G10="Y",H10*I10,0) -> 0 | K10: ='Annual Election'!E13 | L10: ='Annual Election'!H13 | M10: =IF(OR(K10="",L10=""),"",ROUNDUP((L10-K10+1)/7,0)) | N10: =IF(OR(J10="",M10="",M10=0),0,J10/M10) -> 0
A11: =Master!A$6 -> 0 | B11: =Master!B$6 -> 0 | C11: ='Activity List'!A11 -> T1-010 | D11: ='Activity List'!D11 -> Mulch Application | E11: ='Activity List'!B11 -> Tier 1 — Core Services | F11: ='Activity List'!E11 -> bed | G11: ='Annual Election'!I14 -> 0 | I11: =IFERROR(INDEX('Labor Rate Card'!$G$2:$G$135,MATCH(C11,'Labor Rate Card'!$A$2:$A$135,0)),0) -> 0 | J11: =IF(G11="Y",H11*I11,0) -> 0 | K11: ='Annual Election'!E14 | L11: ='Annual Election'!H14 | M11: =IF(OR(K11="",L11=""),"",ROUNDUP((L11-K11+1)/7,0)) | N11: =IF(OR(J11="",M11="",M11=0),0,J11/M11) -> 0
A12: =Master!A$6 -> 0 | B12: =Master!B$6 -> 0 | C12: ='Activity List'!A12 -> T1-011 | D12: ='Activity List'!D12 -> Shade Material Preparation | E12: ='Activity List'!B12 -> Tier 1 — Core Services | F12: ='Activity List'!E12 -> bed | G12: ='Annual Election'!I15 -> 0 | I12: =IFERROR(INDEX('Labor Rate Card'!$G$2:$G$135,MATCH(C12,'Labor Rate Card'!$A$2:$A$135,0)),0) -> 0 | J12: =IF(G12="Y",H12*I12,0) -> 0 | K12: ='Annual Election'!E15 | L12: ='Annual Election'!H15 | M12: =IF(OR(K12="",L12=""),"",ROUNDUP((L12-K12+1)/7,0)) | N12: =IF(OR(J12="",M12="",M12=0),0,J12/M12) -> 0
A13: =Master!A$6 -> 0 | B13: =Master!B$6 -> 0 | C13: ='Activity List'!A13 -> T1-012 | D13: ='Activity List'!D13 -> Shade Construction | E13: ='Activity List'!B13 -> Tier 1 — Core Services | F13: ='Activity List'!E13 -> bed | G13: ='Annual Election'!I16 -> 0 | I13: =IFERROR(INDEX('Labor Rate Card'!$G$2:$G$135,MATCH(C13,'Labor Rate Card'!$A$2:$A$135,0)),0) -> 0 | J13: =IF(G13="Y",H13*I13,0) -> 0 | K13: ='Annual Election'!E16 | L13: ='Annual Election'!H16 | M13: =IF(OR(K13="",L13=""),"",ROUNDUP((L13-K13+1)/7,0)) | N13: =IF(OR(J13="",M13="",M13=0),0,J13/M13) -> 0
... A135: =Master!A$6 -> 0 | B135: =Master!B$6 -> 0 | C135: ='Activity List'!A135 -> T3-035 | D135: ='Activity List'!D135 -> Buyer Hosting at SpiralLabs | E135: ='Activity List'!B135 -> Tier 3 — Interventions | F135: ='Activity List'!E135 -> event | G135: ='Annual Election'!I138 -> N | I135: =IFERROR(INDEX('Labor Rate Card'!$G$2:$G$135,MATCH(C135,'Labor Rate Card'!$A$2:$A$135,0)),0) -> 0 | J135: =IF(G135="Y",H135*I135,0) -> 0 | K135: ='Annual Election'!E138 -> 0 | L135: ='Annual Election'!H138 -> 0 | M135: =IF(OR(K135="",L135=""),"",ROUNDUP((L135-K135+1)/7,0)) -> 1 | N135: =IF(OR(J135="",M135="",M135=0),0,J135/M135) -> 0
A137: Tick (Y/N) now reads from the Annual Election sheet — election happens there first. Planned Qty is the magnitude of work for this block: how many hectares, trees, beds etc. this activity actually needs, entered once elected. Columns K-N are helper columns (window, weeks spanned, weekly allocation) feeding the Weekly Cash Flow sheet. To plan a second block: generate a matching set of Election and Activity Plan rows for that block, plus its own Calendar tab.

Sheet Supervisor Progress
A1: Block ID | B1: Activity ID | C1: Activity Name | D1: Planned Qty | E1: Window Start | F1: Effective End | G1: % Complete (25/50/75/100) | H1: Actual Qty Done | I1: Labor Cost Booked (ETB) | J1: Variance Qty (Planned - Actual) | K1: Last Movement Date (update manually when % changes) | L1: Weeks Since Movement | M1: Stall Flag (2+ weeks) | N1: Rollover Qty (if window closed, <100%) | O1: Rollover Flag | P1: Flagged Activity (helper, for report)
A2: ='Activity Plan'!A2 -> 0 | B2: ='Activity Plan'!C2 -> T1-001 | C2: ='Activity Plan'!D2 -> Land Clearing | D2: ='Activity Plan'!H2 -> 0 | E2: ='Annual Election'!E5 | F2: ='Annual Election'!H5 | H2: =IF(OR(D2="",G2=""),"",D2*G2/100) | I2: =IF(H2="","",H2*'Activity Plan'!I2) | J2: =IF(H2="","",D2-H2) | L2: =IF(K2="","",(TODAY()-K2)/7) | M2: =IF(AND(L2<>"",L2>=2,G2<100),"AT RISK — no progress in 2+ weeks","") | N2: =IF(AND(F2<>"",TODAY()>F2,OR(G2="",G2<100)),D2-IF(H2="",0,H2),0) -> 0 | O2: =IF(N2>0,"ROLL OVER — create a new Election/Activity Plan entry for the shortfall","") | P2: =IF(M2<>"",C2,"")
A3: ='Activity Plan'!A3 -> 0 | B3: ='Activity Plan'!C3 -> T1-002 | C3: ='Activity Plan'!D3 -> Tree Felling | D3: ='Activity Plan'!H3 -> 0 | E3: ='Annual Election'!E6 | F3: ='Annual Election'!H6 | H3: =IF(OR(D3="",G3=""),"",D3*G3/100) | I3: =IF(H3="","",H3*'Activity Plan'!I3) | J3: =IF(H3="","",D3-H3) | L3: =IF(K3="","",(TODAY()-K3)/7) | M3: =IF(AND(L3<>"",L3>=2,G3<100),"AT RISK — no progress in 2+ weeks","") | N3: =IF(AND(F3<>"",TODAY()>F3,OR(G3="",G3<100)),D3-IF(H3="",0,H3),0) -> 0 | O3: =IF(N3>0,"ROLL OVER — create a new Election/Activity Plan entry for the shortfall","") | P3: =IF(M3<>"",C3,"")
A4: ='Activity Plan'!A4 -> 0 | B4: ='Activity Plan'!C4 -> T1-003 | C4: ='Activity Plan'!D4 -> Soil Heaping | D4: ='Activity Plan'!H4 -> 0 | E4: ='Annual Election'!E7 | F4: ='Annual Election'!H7 | H4: =IF(OR(D4="",G4=""),"",D4*G4/100) | I4: =IF(H4="","",H4*'Activity Plan'!I4) | J4: =IF(H4="","",D4-H4) | L4: =IF(K4="","",(TODAY()-K4)/7) | M4: =IF(AND(L4<>"",L4>=2,G4<100),"AT RISK — no progress in 2+ weeks","") | N4: =IF(AND(F4<>"",TODAY()>F4,OR(G4="",G4<100)),D4-IF(H4="",0,H4),0) -> 0 | O4: =IF(N4>0,"ROLL OVER — create a new Election/Activity Plan entry for the shortfall","") | P4: =IF(M4<>"",C4,"")
A5: ='Activity Plan'!A5 -> 0 | B5: ='Activity Plan'!C5 -> T1-004 | C5: ='Activity Plan'!D5 -> Polytube Cutting | D5: ='Activity Plan'!H5 -> 0 | E5: ='Annual Election'!E8 | F5: ='Annual Election'!H8 | H5: =IF(OR(D5="",G5=""),"",D5*G5/100) | I5: =IF(H5="","",H5*'Activity Plan'!I5) | J5: =IF(H5="","",D5-H5) | L5: =IF(K5="","",(TODAY()-K5)/7) | M5: =IF(AND(L5<>"",L5>=2,G5<100),"AT RISK — no progress in 2+ weeks","") | N5: =IF(AND(F5<>"",TODAY()>F5,OR(G5="",G5<100)),D5-IF(H5="",0,H5),0) -> 0 | O5: =IF(N5>0,"ROLL OVER — create a new Election/Activity Plan entry for the shortfall","") | P5: =IF(M5<>"",C5,"")
A6: ='Activity Plan'!A6 -> 0 | B6: ='Activity Plan'!C6 -> T1-005 | C6: ='Activity Plan'!D6 -> Polytube Filling | D6: ='Activity Plan'!H6 -> 0 | E6: ='Annual Election'!E9 | F6: ='Annual Election'!H9 | H6: =IF(OR(D6="",G6=""),"",D6*G6/100) | I6: =IF(H6="","",H6*'Activity Plan'!I6) | J6: =IF(H6="","",D6-H6) | L6: =IF(K6="","",(TODAY()-K6)/7) | M6: =IF(AND(L6<>"",L6>=2,G6<100),"AT RISK — no progress in 2+ weeks","") | N6: =IF(AND(F6<>"",TODAY()>F6,OR(G6="",G6<100)),D6-IF(H6="",0,H6),0) -> 0 | O6: =IF(N6>0,"ROLL OVER — create a new Election/Activity Plan entry for the shortfall","") | P6: =IF(M6<>"",C6,"")
A7: ='Activity Plan'!A7 -> 0 | B7: ='Activity Plan'!C7 -> T1-006 | C7: ='Activity Plan'!D7 -> Seedbed Preparation | D7: ='Activity Plan'!H7 -> 0 | E7: ='Annual Election'!E10 | F7: ='Annual Election'!H10 | H7: =IF(OR(D7="",G7=""),"",D7*G7/100) | I7: =IF(H7="","",H7*'Activity Plan'!I7) | J7: =IF(H7="","",D7-H7) | L7: =IF(K7="","",(TODAY()-K7)/7) | M7: =IF(AND(L7<>"",L7>=2,G7<100),"AT RISK — no progress in 2+ weeks","") | N7: =IF(AND(F7<>"",TODAY()>F7,OR(G7="",G7<100)),D7-IF(H7="",0,H7),0) -> 0 | O7: =IF(N7>0,"ROLL OVER — create a new Election/Activity Plan entry for the shortfall","") | P7: =IF(M7<>"",C7,"")
A8: ='Activity Plan'!A8 -> 0 | B8: ='Activity Plan'!C8 -> T1-007 | C8: ='Activity Plan'!D8 -> Polytube Arranging | D8: ='Activity Plan'!H8 -> 0 | E8: ='Annual Election'!E11 | F8: ='Annual Election'!H11 | H8: =IF(OR(D8="",G8=""),"",D8*G8/100) | I8: =IF(H8="","",H8*'Activity Plan'!I8) | J8: =IF(H8="","",D8-H8) | L8: =IF(K8="","",(TODAY()-K8)/7) | M8: =IF(AND(L8<>"",L8>=2,G8<100),"AT RISK — no progress in 2+ weeks","") | N8: =IF(AND(F8<>"",TODAY()>F8,OR(G8="",G8<100)),D8-IF(H8="",0,H8),0) -> 0 | O8: =IF(N8>0,"ROLL OVER — create a new Election/Activity Plan entry for the shortfall","") | P8: =IF(M8<>"",C8,"")
A9: ='Activity Plan'!A9 -> 0 | B9: ='Activity Plan'!C9 -> T1-008 | C9: ='Activity Plan'!D9 -> Seed Sowing | D9: ='Activity Plan'!H9 -> 0 | E9: ='Annual Election'!E12 | F9: ='Annual Election'!H12 | H9: =IF(OR(D9="",G9=""),"",D9*G9/100) | I9: =IF(H9="","",H9*'Activity Plan'!I9) | J9: =IF(H9="","",D9-H9) | L9: =IF(K9="","",(TODAY()-K9)/7) | M9: =IF(AND(L9<>"",L9>=2,G9<100),"AT RISK — no progress in 2+ weeks","") | N9: =IF(AND(F9<>"",TODAY()>F9,OR(G9="",G9<100)),D9-IF(H9="",0,H9),0) -> 0 | O9: =IF(N9>0,"ROLL OVER — create a new Election/Activity Plan entry for the shortfall","") | P9: =IF(M9<>"",C9,"")
A10: ='Activity Plan'!A10 -> 0 | B10: ='Activity Plan'!C10 -> T1-009 | C10: ='Activity Plan'!D10 -> Mulch Material Preparation | D10: ='Activity Plan'!H10 -> 0 | E10: ='Annual Election'!E13 | F10: ='Annual Election'!H13 | H10: =IF(OR(D10="",G10=""),"",D10*G10/100) | I10: =IF(H10="","",H10*'Activity Plan'!I10) | J10: =IF(H10="","",D10-H10) | L10: =IF(K10="","",(TODAY()-K10)/7) | M10: =IF(AND(L10<>"",L10>=2,G10<100),"AT RISK — no progress in 2+ weeks","") | N10: =IF(AND(F10<>"",TODAY()>F10,OR(G10="",G10<100)),D10-IF(H10="",0,H10),0) -> 0 | O10: =IF(N10>0,"ROLL OVER — create a new Election/Activity Plan entry for the shortfall","") | P10: =IF(M10<>"",C10,"")
A11: ='Activity Plan'!A11 -> 0 | B11: ='Activity Plan'!C11 -> T1-010 | C11: ='Activity Plan'!D11 -> Mulch Application | D11: ='Activity Plan'!H11 -> 0 | E11: ='Annual Election'!E14 | F11: ='Annual Election'!H14 | H11: =IF(OR(D11="",G11=""),"",D11*G11/100) | I11: =IF(H11="","",H11*'Activity Plan'!I11) | J11: =IF(H11="","",D11-H11) | L11: =IF(K11="","",(TODAY()-K11)/7) | M11: =IF(AND(L11<>"",L11>=2,G11<100),"AT RISK — no progress in 2+ weeks","") | N11: =IF(AND(F11<>"",TODAY()>F11,OR(G11="",G11<100)),D11-IF(H11="",0,H11),0) -> 0 | O11: =IF(N11>0,"ROLL OVER — create a new Election/Activity Plan entry for the shortfall","") | P11: =IF(M11<>"",C11,"")
A12: ='Activity Plan'!A12 -> 0 | B12: ='Activity Plan'!C12 -> T1-011 | C12: ='Activity Plan'!D12 -> Shade Material Preparation | D12: ='Activity Plan'!H12 -> 0 | E12: ='Annual Election'!E15 | F12: ='Annual Election'!H15 | H12: =IF(OR(D12="",G12=""),"",D12*G12/100) | I12: =IF(H12="","",H12*'Activity Plan'!I12) | J12: =IF(H12="","",D12-H12) | L12: =IF(K12="","",(TODAY()-K12)/7) | M12: =IF(AND(L12<>"",L12>=2,G12<100),"AT RISK — no progress in 2+ weeks","") | N12: =IF(AND(F12<>"",TODAY()>F12,OR(G12="",G12<100)),D12-IF(H12="",0,H12),0) -> 0 | O12: =IF(N12>0,"ROLL OVER — create a new Election/Activity Plan entry for the shortfall","") | P12: =IF(M12<>"",C12,"")
A13: ='Activity Plan'!A13 -> 0 | B13: ='Activity Plan'!C13 -> T1-012 | C13: ='Activity Plan'!D13 -> Shade Construction | D13: ='Activity Plan'!H13 -> 0 | E13: ='Annual Election'!E16 | F13: ='Annual Election'!H16 | H13: =IF(OR(D13="",G13=""),"",D13*G13/100) | I13: =IF(H13="","",H13*'Activity Plan'!I13) | J13: =IF(H13="","",D13-H13) | L13: =IF(K13="","",(TODAY()-K13)/7) | M13: =IF(AND(L13<>"",L13>=2,G13<100),"AT RISK — no progress in 2+ weeks","") | N13: =IF(AND(F13<>"",TODAY()>F13,OR(G13="",G13<100)),D13-IF(H13="",0,H13),0) -> 0 | O13: =IF(N13>0,"ROLL OVER — create a new Election/Activity Plan entry for the shortfall","") | P13: =IF(M13<>"",C13,"")
... A135: ='Activity Plan'!A135 -> 0 | B135: ='Activity Plan'!C135 -> T3-035 | C135: ='Activity Plan'!D135 -> Buyer Hosting at SpiralLabs | D135: ='Activity Plan'!H135 -> 0 | E135: ='Annual Election'!E138 -> 0 | F135: ='Annual Election'!H138 -> 0 | H135: =IF(OR(D135="",G135=""),"",D135*G135/100) | I135: =IF(H135="","",H135*'Activity Plan'!I135) | J135: =IF(H135="","",D135-H135) | L135: =IF(K135="","",(TODAY()-K135)/7) | M135: =IF(AND(L135<>"",L135>=2,G135<100),"AT RISK — no progress in 2+ weeks","") | N135: =IF(AND(F135<>"",TODAY()>F135,OR(G135="",G135<100)),D135-IF(H135="",0,H135),0) -> 0 | O135: =IF(N135>0,"ROLL OVER — create a new Election/Activity Plan entry for the shortfall","") | P135: =IF(M135<>"",C135,"")
A137: % Complete is entered by the field supervisor, weekly, against the Field Ticket record — not a guess. Update Last Movement Date by hand whenever % actually changes; the Stall Flag and rollover logic both depend on that date being kept current. Rollover Qty and Rollover Flag are calculated warnings, not automatic actions — plain formulas cannot create new rows on their own, so a flagged rollover still needs a new Annual Election / Activity Plan entry created by hand for the shortfall, in the next appropriate window.

Sheet Labor Budget
A1: Block ID | B1: Block Name | C1: Tier 1 — Core Services Labor Cost (ETB) | D1: Tier 2 — Projects Labor Cost (ETB) | E1: Tier 3 — Interventions Labor Cost (ETB) | F1: Block Total Labor Cost (ETB)
A2: =Master!A$6 -> 0 | B2: =Master!B$6 -> 0 | C2: =SUMIFS('Activity Plan'!$J$2:$J$135,'Activity Plan'!$A$2:$A$135,A2,'Activity Plan'!$E$2:$E$135,"Tier 1 — Core Services") -> 0 | D2: =SUMIFS('Activity Plan'!$J$2:$J$135,'Activity Plan'!$A$2:$A$135,A2,'Activity Plan'!$E$2:$E$135,"Tier 2 — Projects") -> 0 | E2: =SUMIFS('Activity Plan'!$J$2:$J$135,'Activity Plan'!$A$2:$A$135,A2,'Activity Plan'!$E$2:$E$135,"Tier 3 — Interventions") -> 0 | F2: =SUM(C2:E2) -> 0
B3: Farm Total | C3: =SUM(C2:C2) -> 0 | D3: =SUM(D2:D2) -> 0 | E3: =SUM(E2:E2) -> 0 | F3: =SUM(F2:F2) -> 0
A5: Add a row per block as Master grows; copy the formulas across.

Sheet Material Budget
A1: Block ID | B1: Activity ID | C1: Activity Name | D1: Material ID | E1: Material Norm (qty / activity unit) | F1: Material Rate (ETB / qty) | G1: Planned Activity Qty (from Activity Plan) | H1: Planned Material Qty | I1: Planned Material Cost (ETB) | J1: Window Start (helper) | K1: Window End (helper) | L1: Months Spanned (helper) | M1: Monthly Allocation (ETB, helper)
A2: =Master!A$6 -> 0 | C2: =IFERROR(INDEX('Activity List'!$D$2:$D$135,MATCH(B2,'Activity List'!$A$2:$A$135,0)),"") | F2: =IFERROR(INDEX('Material Rate Card'!$D$2:$D$11,MATCH(D2,'Material Rate Card'!$A$2:$A$11,0)),0) -> 0 | G2: =IFERROR(SUMIFS('Activity Plan'!$H$2:$H$135,'Activity Plan'!$A$2:$A$135,A2,'Activity Plan'!$C$2:$C$135,B2),0) -> 0 | H2: =G2*E2 -> 0 | I2: =H2*F2 -> 0 | J2: =IFERROR(INDEX('Annual Election'!$E$2:$E$138,MATCH(B2,'Annual Election'!$B$2:$B$138,0)),"") | K2: =IFERROR(INDEX('Annual Election'!$H$2:$H$138,MATCH(B2,'Annual Election'!$B$2:$B$138,0)),"") | L2: =IF(OR(J2="",K2=""),"",DATEDIF(J2,K2,"m")+1) | M2: =IF(OR(I2="",L2="",L2=0),0,I2/L2) -> 0
